Script started on Sun Jul 17 13:29:20 2022
[1m[7m%[27m[1m[0m                                                      [0m[27m[24m[Jmichelecatani@MacBook-Pro back-end % [K[?2004hppython3[?2004l
Python 3.10.1 (v3.10.1:2cd268a3a9, Dec  6 2021, 14:28:59) [Clang 13.0.0 (clang-1300.0.29.3)] on darwin
Type "help", "copyright", "credits" or "license" for more information.
>>> from flaskServer import create_app, db
>>> app = create_app()
/Library/Frameworks/Python.framework/Versions/3.10/lib/python3.10/site-packages/flask_sqlalchemy/__init__.py:872: FSADeprecationWarning: SQLALCHEMY_TRACK_MODIFICATIONS adds significant overhead and will be disabled by default in the future.  Set it to True or False to suppress this warning.
  warnings.warn(FSADeprecationWarning(
Created Database!
>>> app.app_context().push()
>>> db.create_all()
>>> from flaskServer.models.puy[K[K[K[K import User
>>> users = User.query.all()
>>> for i in uder[K[K[Kser:
...     [K...[9Gprint(i.email)
... 
Traceback (most recent call last):
  File "<stdin>", line 1, in <module>
NameError: name 'user' is not defined. Did you mean: 'User'?
>>>     print(i.email)[K[K[K[K[K[K[K[K[K[K[K[K[K[Kfor i in users :
...     [K...[9Gprint(i.email)
... 
hello
dylan
asdasd
sefsdfsdfsdf

heyMan
dybourqu@gmail.com
>>>     print(i.email)[5Gfor i in users:[K[5G    print(i.email)[5Gfor i in user:[K[5Gusers = User.query.all()[K[K[K[K[K[K[K[K[K[K[K[K[K[K[K[KItems[K.query.all()
Traceback (most recent call last):
  File "<stdin>", line 1, in <module>
NameError: name 'Item' is not defined. Did you mean: 'iter'?
>>> from import [K[K[K[K[K[KflaskServer.models import Item
>>> from flaskServer.models import Item[5Gusers = Item.query.all()[K[5G    print(i.email)[K[5Gusers = Item.query.all()
>>> for i in users:
...     [K...[9G[rint[K[K[K[K[Kprint(i.name)
... 
golfClub
khabib
>>> from flawk[K[KskServer.models import Item
>>> from flaskServer.models import Item[5G    print(i.name)[K[5Gfor i in users:[K[5G[9P[10G = Item.query.all()[5Gfrom flaskServer.models import Item[5Gusers = Item.query.all()[K
>>> pr[K[Kfor i int[K users:
...     [K...[9Gprint(i)
... 
Item()
Item()
>>> 
KeyboardInterrupt
>>> 
zsh: suspended  python3
[1m[7m%[27m[1m[0m                                                      [0m[27m[24m[Jmichelecatani@MacBook-Pro back-end % [K[?2004heexport f FLASK_APP= [Krrun.  r [K[?2004l
[1m[7m%[27m[1m[0m                                                      [0m[27m[24m[Jmichelecatani@MacBook-Pro back-end % [K[?2004heexport FLASK_APP= [Krrun.py[?2004l
[1m[7m%[27m[1m[0m                                                      [0m[27m[24m[Jmichelecatani@MacBook-Pro back-end % [K[?2004heexport FLASK+ _APP= [K[K[?2004l
[1m[7m%[27m[1m[0m                                                      [0m[27m[24m[Jmichelecatani@MacBook-Pro back-end % [K[?2004hfflask run[?2004l
 * Serving Flask app '' (lazy loading)
 * Environment: production
[31m   WARNING: This is a development server. Do not use it in a production deployment.[0m
[2m   Use a production WSGI server instead.[0m
 * Debug mode: off
Usage: flask run [OPTIONS]
Try 'flask run --help' for help.

Error: Could not locate a Flask application. You did not provide the "FLASK_APP" environment variable, and a "wsgi.py" or "app.py" module was not found in the current directory.
[1m[7m%[27m[1m[0m                                                      [0m[27m[24m[Jmichelecatani@MacBook-Pro back-end % [K[?2004heexport FLASK_APP= [Krrun.py[?2004l
[1m[7m%[27m[1m[0m                                                      [0m[27m[24m[Jmichelecatani@MacBook-Pro back-end % [K[?2004heexport FLASK_APP   DE  ENV= [Kddevelopment[?2004l
[1m[7m%[27m[1m[0m                                                      [0m[27m[24m[Jmichelecatani@MacBook-Pro back-end % [K[?2004hfflask run[?2004l
 * Serving Flask app 'run.py' (lazy loading)
 * Environment: development
 * Debug mode: on
/Library/Frameworks/Python.framework/Versions/3.10/lib/python3.10/site-packages/flask_sqlalchemy/__init__.py:872: FSADeprecationWarning: SQLALCHEMY_TRACK_MODIFICATIONS adds significant overhead and will be disabled by default in the future.  Set it to True or False to suppress this warning.
  warnings.warn(FSADeprecationWarning(
Traceback (most recent call last):
  File "/Library/Frameworks/Python.framework/Versions/3.10/bin/flask", line 8, in <module>
    sys.exit(main())
  File "/Library/Frameworks/Python.framework/Versions/3.10/lib/python3.10/site-packages/flask/cli.py", line 988, in main
    cli.main()
  File "/Library/Frameworks/Python.framework/Versions/3.10/lib/python3.10/site-packages/flask/cli.py", line 579, in main
    return super().main(*args, **kwargs)
  File "/Library/Frameworks/Python.framework/Versions/3.10/lib/python3.10/site-packages/click/core.py", line 1055, in main
    rv = self.invoke(ctx)
  File "/Library/Frameworks/Python.framework/Versions/3.10/lib/python3.10/site-packages/click/core.py", line 1657, in invoke
    return _process_result(sub_ctx.command.invoke(sub_ctx))
  File "/Library/Frameworks/Python.framework/Versions/3.10/lib/python3.10/site-packages/click/core.py", line 1404, in invoke
    return ctx.invoke(self.callback, **ctx.params)
  File "/Library/Frameworks/Python.framework/Versions/3.10/lib/python3.10/site-packages/click/core.py", line 760, in invoke
    return __callback(*args, **kwargs)
  File "/Library/Frameworks/Python.framework/Versions/3.10/lib/python3.10/site-packages/click/decorators.py", line 84, in new_func
    return ctx.invoke(f, obj, *args, **kwargs)
  File "/Library/Frameworks/Python.framework/Versions/3.10/lib/python3.10/site-packages/click/core.py", line 760, in invoke
    return __callback(*args, **kwargs)
  File "/Library/Frameworks/Python.framework/Versions/3.10/lib/python3.10/site-packages/flask/cli.py", line 850, in run_command
    app = DispatchingApp(info.load_app, use_eager_loading=eager_loading)
  File "/Library/Frameworks/Python.framework/Versions/3.10/lib/python3.10/site-packages/flask/cli.py", line 299, in __init__
    self._load_unlocked()
  File "/Library/Frameworks/Python.framework/Versions/3.10/lib/python3.10/site-packages/flask/cli.py", line 333, in _load_unlocked
    self._app = rv = self.loader()
  File "/Library/Frameworks/Python.framework/Versions/3.10/lib/python3.10/site-packages/flask/cli.py", line 389, in load_app
    app = locate_app(import_name, name)
  File "/Library/Frameworks/Python.framework/Versions/3.10/lib/python3.10/site-packages/flask/cli.py", line 234, in locate_app
    __import__(module_name)
  File "/Users/michelecatani/Desktop/school/4semCompSci/3340/project/3340Project/back-end/run.py", line 3, in <module>
    app = create_app()
  File "/Users/michelecatani/Desktop/school/4semCompSci/3340/project/3340Project/back-end/flaskServer/__init__.py", line 30, in create_app
    app.register_blueprint(auth, url_prefix='/auth/')
  File "/Library/Frameworks/Python.framework/Versions/3.10/lib/python3.10/site-packages/flask/scaffold.py", line 56, in wrapper_func
    return f(self, *args, **kwargs)
  File "/Library/Frameworks/Python.framework/Versions/3.10/lib/python3.10/site-packages/flask/app.py", line 1028, in register_blueprint
    blueprint.register(self, options)
  File "/Library/Frameworks/Python.framework/Versions/3.10/lib/python3.10/site-packages/flask/blueprints.py", line 360, in register
    deferred(state)
  File "/Library/Frameworks/Python.framework/Versions/3.10/lib/python3.10/site-packages/flask/blueprints.py", line 411, in <lambda>
    lambda s: s.add_url_rule(
  File "/Library/Frameworks/Python.framework/Versions/3.10/lib/python3.10/site-packages/flask/blueprints.py", line 103, in add_url_rule
    self.app.add_url_rule(
  File "/Library/Frameworks/Python.framework/Versions/3.10/lib/python3.10/site-packages/flask/scaffold.py", line 56, in wrapper_func
    return f(self, *args, **kwargs)
  File "/Library/Frameworks/Python.framework/Versions/3.10/lib/python3.10/site-packages/flask/app.py", line 1090, in add_url_rule
    raise AssertionError(
AssertionError: View function mapping is overwriting an existing endpoint function: auth.create_token
[1m[7m%[27m[1m[0m                                                      [0m[27m[24m[Jmichelecatani@MacBook-Pro back-end % [K[?2004hflask run[9Dexport FLASK_ENV=development[K[A[39CAPP[1Brun.py[K[A[31Cflask run[K[1B[K[A[46C[9Dexport FLASK_APP=run.py[K[A[44CENV[1Bdevelopment[A[39CAPP[1Brun.py     [?2004l
[1m[7m%[27m[1m[0m                                                      [0m[27m[24m[Jmichelecatani@MacBook-Pro back-end % [K[?2004hexport FLASK_APP=run.py[K[A[31Cflask run[K[1B[K[A[46C[9Dexport FLASK_ENV=development[K[?2004l
[1m[7m%[27m[1m[0m                                                      [0m[27m[24m[Jmichelecatani@MacBook-Pro back-end % [K[?2004hexport FLASK_ENV=development[K[A[39CAPP[1Brun.py[K[A[31Cflask run[K[1B[K[A[46C[?2004l[1B * Serving Flask app 'run.py' (lazy loading)
 * Environment: development
 * Debug mode: on
/Library/Frameworks/Python.framework/Versions/3.10/lib/python3.10/site-packages/flask_sqlalchemy/__init__.py:872: FSADeprecationWarning: SQLALCHEMY_TRACK_MODIFICATIONS adds significant overhead and will be disabled by default in the future.  Set it to True or False to suppress this warning.
  warnings.warn(FSADeprecationWarning(
Created Database!
 * Running on http://127.0.0.1:5000 (Press CTRL+C to quit)
 * Restarting with stat
 * Debugger is active!
 * Debugger PIN: 371-262-178
/Library/Frameworks/Python.framework/Versions/3.10/lib/python3.10/site-packages/flask_sqlalchemy/__init__.py:872: FSADeprecationWarning: SQLALCHEMY_TRACK_MODIFICATIONS adds significant overhead and will be disabled by default in the future.  Set it to True or False to suppress this warning.
  warnings.warn(FSADeprecationWarning(
Created Database!
127.0.0.1 - - [17/Jul/2022 16:10:37] "GET /items/items HTTP/1.1" 200 -
127.0.0.1 - - [17/Jul/2022 16:10:37] "GET /items/items HTTP/1.1" 200 -
127.0.0.1 - - [17/Jul/2022 16:10:39] "GET /items/items HTTP/1.1" 200 -
127.0.0.1 - - [17/Jul/2022 16:10:39] "GET /items/items HTTP/1.1" 200 -
127.0.0.1 - - [17/Jul/2022 16:10:41] "GET /auth/ourNames HTTP/1.1" 200 -
127.0.0.1 - - [17/Jul/2022 16:10:41] "GET /auth/ourNames HTTP/1.1" 200 -
127.0.0.1 - - [17/Jul/2022 16:10:44] "GET /auth/ourNames HTTP/1.1" 200 -
127.0.0.1 - - [17/Jul/2022 16:10:44] "GET /auth/ourNames HTTP/1.1" 200 -
127.0.0.1 - - [17/Jul/2022 16:10:45] "GET /items/items HTTP/1.1" 200 -
127.0.0.1 - - [17/Jul/2022 16:10:45] "GET /items/items HTTP/1.1" 200 -
127.0.0.1 - - [17/Jul/2022 16:10:51] "GET /items/items HTTP/1.1" 200 -
127.0.0.1 - - [17/Jul/2022 16:10:51] "GET /items/items HTTP/1.1" 200 -
^C[1m[7m%[27m[1m[0m                                                      [0m[27m[24m[Jmichelecatani@MacBook-Pro back-end % [K[?2004heexport Flask         e  fflask run[?2004l
 * Serving Flask app 'run.py' (lazy loading)
 * Environment: development
 * Debug mode: on
/Library/Frameworks/Python.framework/Versions/3.10/lib/python3.10/site-packages/flask_sqlalchemy/__init__.py:872: FSADeprecationWarning: SQLALCHEMY_TRACK_MODIFICATIONS adds significant overhead and will be disabled by default in the future.  Set it to True or False to suppress this warning.
  warnings.warn(FSADeprecationWarning(
Created Database!
 * Running on http://127.0.0.1:5000 (Press CTRL+C to quit)
 * Restarting with stat
 * Debugger is active!
 * Debugger PIN: 371-262-178
/Library/Frameworks/Python.framework/Versions/3.10/lib/python3.10/site-packages/flask_sqlalchemy/__init__.py:872: FSADeprecationWarning: SQLALCHEMY_TRACK_MODIFICATIONS adds significant overhead and will be disabled by default in the future.  Set it to True or False to suppress this warning.
  warnings.warn(FSADeprecationWarning(
Created Database!
127.0.0.1 - - [17/Jul/2022 16:51:24] "[33mGET / HTTP/1.1[0m" 404 -
127.0.0.1 - - [17/Jul/2022 16:51:24] "[33mGET /favicon.ico HTTP/1.1[0m" 404 -
127.0.0.1 - - [17/Jul/2022 16:51:39] "GET /auth/ourNames HTTP/1.1" 200 -
127.0.0.1 - - [17/Jul/2022 16:51:39] "GET /auth/ourNames HTTP/1.1" 200 -
127.0.0.1 - - [17/Jul/2022 16:56:29] "GET /items/items HTTP/1.1" 200 -
127.0.0.1 - - [17/Jul/2022 16:56:29] "GET /items/items HTTP/1.1" 200 -
127.0.0.1 - - [17/Jul/2022 16:56:32] "GET /items/items HTTP/1.1" 200 -
127.0.0.1 - - [17/Jul/2022 16:56:35] "[35m[1mGET /items/seeItem?id=[object%20Object] HTTP/1.1[0m" 500 -
Traceback (most recent call last):
  File "/Library/Frameworks/Python.framework/Versions/3.10/lib/python3.10/site-packages/flask/app.py", line 2095, in __call__
    return self.wsgi_app(environ, start_response)
  File "/Library/Frameworks/Python.framework/Versions/3.10/lib/python3.10/site-packages/flask/app.py", line 2080, in wsgi_app
    response = self.handle_exception(e)
  File "/Library/Frameworks/Python.framework/Versions/3.10/lib/python3.10/site-packages/flask_cors/extension.py", line 165, in wrapped_function
    return cors_after_request(app.make_response(f(*args, **kwargs)))
  File "/Library/Frameworks/Python.framework/Versions/3.10/lib/python3.10/site-packages/flask/app.py", line 2077, in wsgi_app
    response = self.full_dispatch_request()
  File "/Library/Frameworks/Python.framework/Versions/3.10/lib/python3.10/site-packages/flask/app.py", line 1525, in full_dispatch_request
    rv = self.handle_user_exception(e)
  File "/Library/Frameworks/Python.framework/Versions/3.10/lib/python3.10/site-packages/flask_cors/extension.py", line 165, in wrapped_function
    return cors_after_request(app.make_response(f(*args, **kwargs)))
  File "/Library/Frameworks/Python.framework/Versions/3.10/lib/python3.10/site-packages/flask/app.py", line 1523, in full_dispatch_request
    rv = self.dispatch_request()
  File "/Library/Frameworks/Python.framework/Versions/3.10/lib/python3.10/site-packages/flask/app.py", line 1509, in dispatch_request
    return self.ensure_sync(self.view_functions[rule.endpoint])(**req.view_args)
  File "/Users/michelecatani/Desktop/school/4semCompSci/3340/project/3340Project/back-end/flaskServer/items.py", line 26, in seeItem
    return jsonify(item.as_dict())
AttributeError: 'NoneType' object has no attribute 'as_dict'
127.0.0.1 - - [17/Jul/2022 16:56:40] "GET /items/items HTTP/1.1" 200 -
127.0.0.1 - - [17/Jul/2022 16:56:40] "GET /items/items HTTP/1.1" 200 -
127.0.0.1 - - [17/Jul/2022 16:56:41] "[35m[1mGET /items/seeItem?id=[object%20Object] HTTP/1.1[0m" 500 -
Traceback (most recent call last):
  File "/Library/Frameworks/Python.framework/Versions/3.10/lib/python3.10/site-packages/flask/app.py", line 2095, in __call__
    return self.wsgi_app(environ, start_response)
  File "/Library/Frameworks/Python.framework/Versions/3.10/lib/python3.10/site-packages/flask/app.py", line 2080, in wsgi_app
    response = self.handle_exception(e)
  File "/Library/Frameworks/Python.framework/Versions/3.10/lib/python3.10/site-packages/flask_cors/extension.py", line 165, in wrapped_function
    return cors_after_request(app.make_response(f(*args, **kwargs)))
  File "/Library/Frameworks/Python.framework/Versions/3.10/lib/python3.10/site-packages/flask/app.py", line 2077, in wsgi_app
    response = self.full_dispatch_request()
  File "/Library/Frameworks/Python.framework/Versions/3.10/lib/python3.10/site-packages/flask/app.py", line 1525, in full_dispatch_request
    rv = self.handle_user_exception(e)
  File "/Library/Frameworks/Python.framework/Versions/3.10/lib/python3.10/site-packages/flask_cors/extension.py", line 165, in wrapped_function
    return cors_after_request(app.make_response(f(*args, **kwargs)))
  File "/Library/Frameworks/Python.framework/Versions/3.10/lib/python3.10/site-packages/flask/app.py", line 1523, in full_dispatch_request
    rv = self.dispatch_request()
  File "/Library/Frameworks/Python.framework/Versions/3.10/lib/python3.10/site-packages/flask/app.py", line 1509, in dispatch_request
    return self.ensure_sync(self.view_functions[rule.endpoint])(**req.view_args)
  File "/Users/michelecatani/Desktop/school/4semCompSci/3340/project/3340Project/back-end/flaskServer/items.py", line 26, in seeItem
    return jsonify(item.as_dict())
AttributeError: 'NoneType' object has no attribute 'as_dict'
127.0.0.1 - - [17/Jul/2022 16:56:42] "GET /items/items HTTP/1.1" 200 -
127.0.0.1 - - [17/Jul/2022 16:56:42] "GET /items/items HTTP/1.1" 200 -
127.0.0.1 - - [17/Jul/2022 16:57:01] "[35m[1mGET /items/seeItem?id=[object%20Object] HTTP/1.1[0m" 500 -
Traceback (most recent call last):
  File "/Library/Frameworks/Python.framework/Versions/3.10/lib/python3.10/site-packages/flask/app.py", line 2095, in __call__
    return self.wsgi_app(environ, start_response)
  File "/Library/Frameworks/Python.framework/Versions/3.10/lib/python3.10/site-packages/flask/app.py", line 2080, in wsgi_app
    response = self.handle_exception(e)
  File "/Library/Frameworks/Python.framework/Versions/3.10/lib/python3.10/site-packages/flask_cors/extension.py", line 165, in wrapped_function
    return cors_after_request(app.make_response(f(*args, **kwargs)))
  File "/Library/Frameworks/Python.framework/Versions/3.10/lib/python3.10/site-packages/flask/app.py", line 2077, in wsgi_app
    response = self.full_dispatch_request()
  File "/Library/Frameworks/Python.framework/Versions/3.10/lib/python3.10/site-packages/flask/app.py", line 1525, in full_dispatch_request
    rv = self.handle_user_exception(e)
  File "/Library/Frameworks/Python.framework/Versions/3.10/lib/python3.10/site-packages/flask_cors/extension.py", line 165, in wrapped_function
    return cors_after_request(app.make_response(f(*args, **kwargs)))
  File "/Library/Frameworks/Python.framework/Versions/3.10/lib/python3.10/site-packages/flask/app.py", line 1523, in full_dispatch_request
    rv = self.dispatch_request()
  File "/Library/Frameworks/Python.framework/Versions/3.10/lib/python3.10/site-packages/flask/app.py", line 1509, in dispatch_request
    return self.ensure_sync(self.view_functions[rule.endpoint])(**req.view_args)
  File "/Users/michelecatani/Desktop/school/4semCompSci/3340/project/3340Project/back-end/flaskServer/items.py", line 26, in seeItem
    return jsonify(item.as_dict())
AttributeError: 'NoneType' object has no attribute 'as_dict'
127.0.0.1 - - [17/Jul/2022 16:57:04] "GET /items/items HTTP/1.1" 200 -
127.0.0.1 - - [17/Jul/2022 16:57:04] "GET /items/items HTTP/1.1" 200 -
127.0.0.1 - - [17/Jul/2022 16:57:15] "[35m[1mGET /items/seeItem?id=[object%20Object] HTTP/1.1[0m" 500 -
Traceback (most recent call last):
  File "/Library/Frameworks/Python.framework/Versions/3.10/lib/python3.10/site-packages/flask/app.py", line 2095, in __call__
    return self.wsgi_app(environ, start_response)
  File "/Library/Frameworks/Python.framework/Versions/3.10/lib/python3.10/site-packages/flask/app.py", line 2080, in wsgi_app
    response = self.handle_exception(e)
  File "/Library/Frameworks/Python.framework/Versions/3.10/lib/python3.10/site-packages/flask_cors/extension.py", line 165, in wrapped_function
    return cors_after_request(app.make_response(f(*args, **kwargs)))
  File "/Library/Frameworks/Python.framework/Versions/3.10/lib/python3.10/site-packages/flask/app.py", line 2077, in wsgi_app
    response = self.full_dispatch_request()
  File "/Library/Frameworks/Python.framework/Versions/3.10/lib/python3.10/site-packages/flask/app.py", line 1525, in full_dispatch_request
    rv = self.handle_user_exception(e)
  File "/Library/Frameworks/Python.framework/Versions/3.10/lib/python3.10/site-packages/flask_cors/extension.py", line 165, in wrapped_function
    return cors_after_request(app.make_response(f(*args, **kwargs)))
  File "/Library/Frameworks/Python.framework/Versions/3.10/lib/python3.10/site-packages/flask/app.py", line 1523, in full_dispatch_request
    rv = self.dispatch_request()
  File "/Library/Frameworks/Python.framework/Versions/3.10/lib/python3.10/site-packages/flask/app.py", line 1509, in dispatch_request
    return self.ensure_sync(self.view_functions[rule.endpoint])(**req.view_args)
  File "/Users/michelecatani/Desktop/school/4semCompSci/3340/project/3340Project/back-end/flaskServer/items.py", line 26, in seeItem
    return jsonify(item.as_dict())
AttributeError: 'NoneType' object has no attribute 'as_dict'
127.0.0.1 - - [17/Jul/2022 16:58:44] "[35m[1mGET /items/seeItem?id=[object%20Object] HTTP/1.1[0m" 500 -
Traceback (most recent call last):
  File "/Library/Frameworks/Python.framework/Versions/3.10/lib/python3.10/site-packages/flask/app.py", line 2095, in __call__
    return self.wsgi_app(environ, start_response)
  File "/Library/Frameworks/Python.framework/Versions/3.10/lib/python3.10/site-packages/flask/app.py", line 2080, in wsgi_app
    response = self.handle_exception(e)
  File "/Library/Frameworks/Python.framework/Versions/3.10/lib/python3.10/site-packages/flask_cors/extension.py", line 165, in wrapped_function
    return cors_after_request(app.make_response(f(*args, **kwargs)))
  File "/Library/Frameworks/Python.framework/Versions/3.10/lib/python3.10/site-packages/flask/app.py", line 2077, in wsgi_app
    response = self.full_dispatch_request()
  File "/Library/Frameworks/Python.framework/Versions/3.10/lib/python3.10/site-packages/flask/app.py", line 1525, in full_dispatch_request
    rv = self.handle_user_exception(e)
  File "/Library/Frameworks/Python.framework/Versions/3.10/lib/python3.10/site-packages/flask_cors/extension.py", line 165, in wrapped_function
    return cors_after_request(app.make_response(f(*args, **kwargs)))
  File "/Library/Frameworks/Python.framework/Versions/3.10/lib/python3.10/site-packages/flask/app.py", line 1523, in full_dispatch_request
    rv = self.dispatch_request()
  File "/Library/Frameworks/Python.framework/Versions/3.10/lib/python3.10/site-packages/flask/app.py", line 1509, in dispatch_request
    return self.ensure_sync(self.view_functions[rule.endpoint])(**req.view_args)
  File "/Users/michelecatani/Desktop/school/4semCompSci/3340/project/3340Project/back-end/flaskServer/items.py", line 26, in seeItem
    return jsonify(item.as_dict())
AttributeError: 'NoneType' object has no attribute 'as_dict'
127.0.0.1 - - [17/Jul/2022 16:58:47] "GET /items/items HTTP/1.1" 200 -
127.0.0.1 - - [17/Jul/2022 16:58:47] "GET /items/items HTTP/1.1" 200 -
127.0.0.1 - - [17/Jul/2022 16:58:49] "[35m[1mGET /items/seeItem?id=[object%20Object] HTTP/1.1[0m" 500 -
Traceback (most recent call last):
  File "/Library/Frameworks/Python.framework/Versions/3.10/lib/python3.10/site-packages/flask/app.py", line 2095, in __call__
    return self.wsgi_app(environ, start_response)
  File "/Library/Frameworks/Python.framework/Versions/3.10/lib/python3.10/site-packages/flask/app.py", line 2080, in wsgi_app
    response = self.handle_exception(e)
  File "/Library/Frameworks/Python.framework/Versions/3.10/lib/python3.10/site-packages/flask_cors/extension.py", line 165, in wrapped_function
    return cors_after_request(app.make_response(f(*args, **kwargs)))
  File "/Library/Frameworks/Python.framework/Versions/3.10/lib/python3.10/site-packages/flask/app.py", line 2077, in wsgi_app
    response = self.full_dispatch_request()
  File "/Library/Frameworks/Python.framework/Versions/3.10/lib/python3.10/site-packages/flask/app.py", line 1525, in full_dispatch_request
    rv = self.handle_user_exception(e)
  File "/Library/Frameworks/Python.framework/Versions/3.10/lib/python3.10/site-packages/flask_cors/extension.py", line 165, in wrapped_function
    return cors_after_request(app.make_response(f(*args, **kwargs)))
  File "/Library/Frameworks/Python.framework/Versions/3.10/lib/python3.10/site-packages/flask/app.py", line 1523, in full_dispatch_request
    rv = self.dispatch_request()
  File "/Library/Frameworks/Python.framework/Versions/3.10/lib/python3.10/site-packages/flask/app.py", line 1509, in dispatch_request
    return self.ensure_sync(self.view_functions[rule.endpoint])(**req.view_args)
  File "/Users/michelecatani/Desktop/school/4semCompSci/3340/project/3340Project/back-end/flaskServer/items.py", line 26, in seeItem
    return jsonify(item.as_dict())
AttributeError: 'NoneType' object has no attribute 'as_dict'
127.0.0.1 - - [17/Jul/2022 16:59:50] "[35m[1mGET /items/seeItem?id=[object%20Object] HTTP/1.1[0m" 500 -
Traceback (most recent call last):
  File "/Library/Frameworks/Python.framework/Versions/3.10/lib/python3.10/site-packages/flask/app.py", line 2095, in __call__
    return self.wsgi_app(environ, start_response)
  File "/Library/Frameworks/Python.framework/Versions/3.10/lib/python3.10/site-packages/flask/app.py", line 2080, in wsgi_app
    response = self.handle_exception(e)
  File "/Library/Frameworks/Python.framework/Versions/3.10/lib/python3.10/site-packages/flask_cors/extension.py", line 165, in wrapped_function
    return cors_after_request(app.make_response(f(*args, **kwargs)))
  File "/Library/Frameworks/Python.framework/Versions/3.10/lib/python3.10/site-packages/flask/app.py", line 2077, in wsgi_app
    response = self.full_dispatch_request()
  File "/Library/Frameworks/Python.framework/Versions/3.10/lib/python3.10/site-packages/flask/app.py", line 1525, in full_dispatch_request
    rv = self.handle_user_exception(e)
  File "/Library/Frameworks/Python.framework/Versions/3.10/lib/python3.10/site-packages/flask_cors/extension.py", line 165, in wrapped_function
    return cors_after_request(app.make_response(f(*args, **kwargs)))
  File "/Library/Frameworks/Python.framework/Versions/3.10/lib/python3.10/site-packages/flask/app.py", line 1523, in full_dispatch_request
    rv = self.dispatch_request()
  File "/Library/Frameworks/Python.framework/Versions/3.10/lib/python3.10/site-packages/flask/app.py", line 1509, in dispatch_request
    return self.ensure_sync(self.view_functions[rule.endpoint])(**req.view_args)
  File "/Users/michelecatani/Desktop/school/4semCompSci/3340/project/3340Project/back-end/flaskServer/items.py", line 26, in seeItem
    return jsonify(item.as_dict())
AttributeError: 'NoneType' object has no attribute 'as_dict'
127.0.0.1 - - [17/Jul/2022 16:59:50] "[35m[1mGET /items/seeItem?id=[object%20Object] HTTP/1.1[0m" 500 -
Traceback (most recent call last):
  File "/Library/Frameworks/Python.framework/Versions/3.10/lib/python3.10/site-packages/flask/app.py", line 2095, in __call__
    return self.wsgi_app(environ, start_response)
  File "/Library/Frameworks/Python.framework/Versions/3.10/lib/python3.10/site-packages/flask/app.py", line 2080, in wsgi_app
    response = self.handle_exception(e)
  File "/Library/Frameworks/Python.framework/Versions/3.10/lib/python3.10/site-packages/flask_cors/extension.py", line 165, in wrapped_function
    return cors_after_request(app.make_response(f(*args, **kwargs)))
  File "/Library/Frameworks/Python.framework/Versions/3.10/lib/python3.10/site-packages/flask/app.py", line 2077, in wsgi_app
    response = self.full_dispatch_request()
  File "/Library/Frameworks/Python.framework/Versions/3.10/lib/python3.10/site-packages/flask/app.py", line 1525, in full_dispatch_request
    rv = self.handle_user_exception(e)
  File "/Library/Frameworks/Python.framework/Versions/3.10/lib/python3.10/site-packages/flask_cors/extension.py", line 165, in wrapped_function
    return cors_after_request(app.make_response(f(*args, **kwargs)))
  File "/Library/Frameworks/Python.framework/Versions/3.10/lib/python3.10/site-packages/flask/app.py", line 1523, in full_dispatch_request
    rv = self.dispatch_request()
  File "/Library/Frameworks/Python.framework/Versions/3.10/lib/python3.10/site-packages/flask/app.py", line 1509, in dispatch_request
    return self.ensure_sync(self.view_functions[rule.endpoint])(**req.view_args)
  File "/Users/michelecatani/Desktop/school/4semCompSci/3340/project/3340Project/back-end/flaskServer/items.py", line 26, in seeItem
    return jsonify(item.as_dict())
AttributeError: 'NoneType' object has no attribute 'as_dict'
127.0.0.1 - - [17/Jul/2022 16:59:50] "[35m[1mGET /items/seeItem?id=[object%20Object] HTTP/1.1[0m" 500 -
Traceback (most recent call last):
  File "/Library/Frameworks/Python.framework/Versions/3.10/lib/python3.10/site-packages/flask/app.py", line 2095, in __call__
    return self.wsgi_app(environ, start_response)
  File "/Library/Frameworks/Python.framework/Versions/3.10/lib/python3.10/site-packages/flask/app.py", line 2080, in wsgi_app
    response = self.handle_exception(e)
  File "/Library/Frameworks/Python.framework/Versions/3.10/lib/python3.10/site-packages/flask_cors/extension.py", line 165, in wrapped_function
    return cors_after_request(app.make_response(f(*args, **kwargs)))
  File "/Library/Frameworks/Python.framework/Versions/3.10/lib/python3.10/site-packages/flask/app.py", line 2077, in wsgi_app
    response = self.full_dispatch_request()
  File "/Library/Frameworks/Python.framework/Versions/3.10/lib/python3.10/site-packages/flask/app.py", line 1525, in full_dispatch_request
    rv = self.handle_user_exception(e)
  File "/Library/Frameworks/Python.framework/Versions/3.10/lib/python3.10/site-packages/flask_cors/extension.py", line 165, in wrapped_function
    return cors_after_request(app.make_response(f(*args, **kwargs)))
  File "/Library/Frameworks/Python.framework/Versions/3.10/lib/python3.10/site-packages/flask/app.py", line 1523, in full_dispatch_request
    rv = self.dispatch_request()
  File "/Library/Frameworks/Python.framework/Versions/3.10/lib/python3.10/site-packages/flask/app.py", line 1509, in dispatch_request
    return self.ensure_sync(self.view_functions[rule.endpoint])(**req.view_args)
  File "/Users/michelecatani/Desktop/school/4semCompSci/3340/project/3340Project/back-end/flaskServer/items.py", line 26, in seeItem
    return jsonify(item.as_dict())
AttributeError: 'NoneType' object has no attribute 'as_dict'
127.0.0.1 - - [17/Jul/2022 16:59:52] "[35m[1mGET /items/seeItem?id=[object%20Object] HTTP/1.1[0m" 500 -
Traceback (most recent call last):
  File "/Library/Frameworks/Python.framework/Versions/3.10/lib/python3.10/site-packages/flask/app.py", line 2095, in __call__
    return self.wsgi_app(environ, start_response)
  File "/Library/Frameworks/Python.framework/Versions/3.10/lib/python3.10/site-packages/flask/app.py", line 2080, in wsgi_app
    response = self.handle_exception(e)
  File "/Library/Frameworks/Python.framework/Versions/3.10/lib/python3.10/site-packages/flask_cors/extension.py", line 165, in wrapped_function
    return cors_after_request(app.make_response(f(*args, **kwargs)))
  File "/Library/Frameworks/Python.framework/Versions/3.10/lib/python3.10/site-packages/flask/app.py", line 2077, in wsgi_app
    response = self.full_dispatch_request()
  File "/Library/Frameworks/Python.framework/Versions/3.10/lib/python3.10/site-packages/flask/app.py", line 1525, in full_dispatch_request
    rv = self.handle_user_exception(e)
  File "/Library/Frameworks/Python.framework/Versions/3.10/lib/python3.10/site-packages/flask_cors/extension.py", line 165, in wrapped_function
    return cors_after_request(app.make_response(f(*args, **kwargs)))
  File "/Library/Frameworks/Python.framework/Versions/3.10/lib/python3.10/site-packages/flask/app.py", line 1523, in full_dispatch_request
    rv = self.dispatch_request()
  File "/Library/Frameworks/Python.framework/Versions/3.10/lib/python3.10/site-packages/flask/app.py", line 1509, in dispatch_request
    return self.ensure_sync(self.view_functions[rule.endpoint])(**req.view_args)
  File "/Users/michelecatani/Desktop/school/4semCompSci/3340/project/3340Project/back-end/flaskServer/items.py", line 26, in seeItem
    return jsonify(item.as_dict())
AttributeError: 'NoneType' object has no attribute 'as_dict'
127.0.0.1 - - [17/Jul/2022 16:59:56] "GET /items/items HTTP/1.1" 200 -
127.0.0.1 - - [17/Jul/2022 16:59:56] "GET /items/items HTTP/1.1" 200 -
127.0.0.1 - - [17/Jul/2022 16:59:58] "[35m[1mGET /items/seeItem?id=[object%20Object] HTTP/1.1[0m" 500 -
Traceback (most recent call last):
  File "/Library/Frameworks/Python.framework/Versions/3.10/lib/python3.10/site-packages/flask/app.py", line 2095, in __call__
    return self.wsgi_app(environ, start_response)
  File "/Library/Frameworks/Python.framework/Versions/3.10/lib/python3.10/site-packages/flask/app.py", line 2080, in wsgi_app
    response = self.handle_exception(e)
  File "/Library/Frameworks/Python.framework/Versions/3.10/lib/python3.10/site-packages/flask_cors/extension.py", line 165, in wrapped_function
    return cors_after_request(app.make_response(f(*args, **kwargs)))
  File "/Library/Frameworks/Python.framework/Versions/3.10/lib/python3.10/site-packages/flask/app.py", line 2077, in wsgi_app
    response = self.full_dispatch_request()
  File "/Library/Frameworks/Python.framework/Versions/3.10/lib/python3.10/site-packages/flask/app.py", line 1525, in full_dispatch_request
    rv = self.handle_user_exception(e)
  File "/Library/Frameworks/Python.framework/Versions/3.10/lib/python3.10/site-packages/flask_cors/extension.py", line 165, in wrapped_function
    return cors_after_request(app.make_response(f(*args, **kwargs)))
  File "/Library/Frameworks/Python.framework/Versions/3.10/lib/python3.10/site-packages/flask/app.py", line 1523, in full_dispatch_request
    rv = self.dispatch_request()
  File "/Library/Frameworks/Python.framework/Versions/3.10/lib/python3.10/site-packages/flask/app.py", line 1509, in dispatch_request
    return self.ensure_sync(self.view_functions[rule.endpoint])(**req.view_args)
  File "/Users/michelecatani/Desktop/school/4semCompSci/3340/project/3340Project/back-end/flaskServer/items.py", line 26, in seeItem
    return jsonify(item.as_dict())
AttributeError: 'NoneType' object has no attribute 'as_dict'
127.0.0.1 - - [17/Jul/2022 17:00:06] "[35m[1mGET /items/seeItem?id=[object%20Object] HTTP/1.1[0m" 500 -
Traceback (most recent call last):
  File "/Library/Frameworks/Python.framework/Versions/3.10/lib/python3.10/site-packages/flask/app.py", line 2095, in __call__
    return self.wsgi_app(environ, start_response)
  File "/Library/Frameworks/Python.framework/Versions/3.10/lib/python3.10/site-packages/flask/app.py", line 2080, in wsgi_app
    response = self.handle_exception(e)
  File "/Library/Frameworks/Python.framework/Versions/3.10/lib/python3.10/site-packages/flask_cors/extension.py", line 165, in wrapped_function
    return cors_after_request(app.make_response(f(*args, **kwargs)))
  File "/Library/Frameworks/Python.framework/Versions/3.10/lib/python3.10/site-packages/flask/app.py", line 2077, in wsgi_app
    response = self.full_dispatch_request()
  File "/Library/Frameworks/Python.framework/Versions/3.10/lib/python3.10/site-packages/flask/app.py", line 1525, in full_dispatch_request
    rv = self.handle_user_exception(e)
  File "/Library/Frameworks/Python.framework/Versions/3.10/lib/python3.10/site-packages/flask_cors/extension.py", line 165, in wrapped_function
    return cors_after_request(app.make_response(f(*args, **kwargs)))
  File "/Library/Frameworks/Python.framework/Versions/3.10/lib/python3.10/site-packages/flask/app.py", line 1523, in full_dispatch_request
    rv = self.dispatch_request()
  File "/Library/Frameworks/Python.framework/Versions/3.10/lib/python3.10/site-packages/flask/app.py", line 1509, in dispatch_request
    return self.ensure_sync(self.view_functions[rule.endpoint])(**req.view_args)
  File "/Users/michelecatani/Desktop/school/4semCompSci/3340/project/3340Project/back-end/flaskServer/items.py", line 26, in seeItem
    return jsonify(item.as_dict())
AttributeError: 'NoneType' object has no attribute 'as_dict'
127.0.0.1 - - [17/Jul/2022 17:00:06] "[35m[1mGET /items/seeItem?id=[object%20Object] HTTP/1.1[0m" 500 -
Traceback (most recent call last):
  File "/Library/Frameworks/Python.framework/Versions/3.10/lib/python3.10/site-packages/flask/app.py", line 2095, in __call__
    return self.wsgi_app(environ, start_response)
  File "/Library/Frameworks/Python.framework/Versions/3.10/lib/python3.10/site-packages/flask/app.py", line 2080, in wsgi_app
    response = self.handle_exception(e)
  File "/Library/Frameworks/Python.framework/Versions/3.10/lib/python3.10/site-packages/flask_cors/extension.py", line 165, in wrapped_function
    return cors_after_request(app.make_response(f(*args, **kwargs)))
  File "/Library/Frameworks/Python.framework/Versions/3.10/lib/python3.10/site-packages/flask/app.py", line 2077, in wsgi_app
    response = self.full_dispatch_request()
  File "/Library/Frameworks/Python.framework/Versions/3.10/lib/python3.10/site-packages/flask/app.py", line 1525, in full_dispatch_request
    rv = self.handle_user_exception(e)
  File "/Library/Frameworks/Python.framework/Versions/3.10/lib/python3.10/site-packages/flask_cors/extension.py", line 165, in wrapped_function
    return cors_after_request(app.make_response(f(*args, **kwargs)))
  File "/Library/Frameworks/Python.framework/Versions/3.10/lib/python3.10/site-packages/flask/app.py", line 1523, in full_dispatch_request
    rv = self.dispatch_request()
  File "/Library/Frameworks/Python.framework/Versions/3.10/lib/python3.10/site-packages/flask/app.py", line 1509, in dispatch_request
    return self.ensure_sync(self.view_functions[rule.endpoint])(**req.view_args)
  File "/Users/michelecatani/Desktop/school/4semCompSci/3340/project/3340Project/back-end/flaskServer/items.py", line 26, in seeItem
    return jsonify(item.as_dict())
AttributeError: 'NoneType' object has no attribute 'as_dict'
127.0.0.1 - - [17/Jul/2022 17:00:09] "[35m[1mGET /items/seeItem?id=undefined HTTP/1.1[0m" 500 -
Traceback (most recent call last):
  File "/Library/Frameworks/Python.framework/Versions/3.10/lib/python3.10/site-packages/flask/app.py", line 2095, in __call__
    return self.wsgi_app(environ, start_response)
  File "/Library/Frameworks/Python.framework/Versions/3.10/lib/python3.10/site-packages/flask/app.py", line 2080, in wsgi_app
    response = self.handle_exception(e)
  File "/Library/Frameworks/Python.framework/Versions/3.10/lib/python3.10/site-packages/flask_cors/extension.py", line 165, in wrapped_function
    return cors_after_request(app.make_response(f(*args, **kwargs)))
  File "/Library/Frameworks/Python.framework/Versions/3.10/lib/python3.10/site-packages/flask/app.py", line 2077, in wsgi_app
    response = self.full_dispatch_request()
  File "/Library/Frameworks/Python.framework/Versions/3.10/lib/python3.10/site-packages/flask/app.py", line 1525, in full_dispatch_request
    rv = self.handle_user_exception(e)
  File "/Library/Frameworks/Python.framework/Versions/3.10/lib/python3.10/site-packages/flask_cors/extension.py", line 165, in wrapped_function
    return cors_after_request(app.make_response(f(*args, **kwargs)))
  File "/Library/Frameworks/Python.framework/Versions/3.10/lib/python3.10/site-packages/flask/app.py", line 1523, in full_dispatch_request
    rv = self.dispatch_request()
  File "/Library/Frameworks/Python.framework/Versions/3.10/lib/python3.10/site-packages/flask/app.py", line 1509, in dispatch_request
    return self.ensure_sync(self.view_functions[rule.endpoint])(**req.view_args)
  File "/Users/michelecatani/Desktop/school/4semCompSci/3340/project/3340Project/back-end/flaskServer/items.py", line 26, in seeItem
    return jsonify(item.as_dict())
AttributeError: 'NoneType' object has no attribute 'as_dict'
127.0.0.1 - - [17/Jul/2022 17:00:09] "[35m[1mGET /items/seeItem?id=undefined HTTP/1.1[0m" 500 -
Traceback (most recent call last):
  File "/Library/Frameworks/Python.framework/Versions/3.10/lib/python3.10/site-packages/flask/app.py", line 2095, in __call__
    return self.wsgi_app(environ, start_response)
  File "/Library/Frameworks/Python.framework/Versions/3.10/lib/python3.10/site-packages/flask/app.py", line 2080, in wsgi_app
    response = self.handle_exception(e)
  File "/Library/Frameworks/Python.framework/Versions/3.10/lib/python3.10/site-packages/flask_cors/extension.py", line 165, in wrapped_function
    return cors_after_request(app.make_response(f(*args, **kwargs)))
  File "/Library/Frameworks/Python.framework/Versions/3.10/lib/python3.10/site-packages/flask/app.py", line 2077, in wsgi_app
    response = self.full_dispatch_request()
  File "/Library/Frameworks/Python.framework/Versions/3.10/lib/python3.10/site-packages/flask/app.py", line 1525, in full_dispatch_request
    rv = self.handle_user_exception(e)
  File "/Library/Frameworks/Python.framework/Versions/3.10/lib/python3.10/site-packages/flask_cors/extension.py", line 165, in wrapped_function
    return cors_after_request(app.make_response(f(*args, **kwargs)))
  File "/Library/Frameworks/Python.framework/Versions/3.10/lib/python3.10/site-packages/flask/app.py", line 1523, in full_dispatch_request
    rv = self.dispatch_request()
  File "/Library/Frameworks/Python.framework/Versions/3.10/lib/python3.10/site-packages/flask/app.py", line 1509, in dispatch_request
    return self.ensure_sync(self.view_functions[rule.endpoint])(**req.view_args)
  File "/Users/michelecatani/Desktop/school/4semCompSci/3340/project/3340Project/back-end/flaskServer/items.py", line 26, in seeItem
    return jsonify(item.as_dict())
AttributeError: 'NoneType' object has no attribute 'as_dict'
127.0.0.1 - - [17/Jul/2022 17:00:12] "GET /items/items HTTP/1.1" 200 -
127.0.0.1 - - [17/Jul/2022 17:00:12] "GET /items/items HTTP/1.1" 200 -
127.0.0.1 - - [17/Jul/2022 17:00:13] "GET /items/items HTTP/1.1" 200 -
127.0.0.1 - - [17/Jul/2022 17:00:13] "GET /items/items HTTP/1.1" 200 -
127.0.0.1 - - [17/Jul/2022 17:00:14] "[35m[1mGET /items/seeItem?id=undefined HTTP/1.1[0m" 500 -
Traceback (most recent call last):
  File "/Library/Frameworks/Python.framework/Versions/3.10/lib/python3.10/site-packages/flask/app.py", line 2095, in __call__
    return self.wsgi_app(environ, start_response)
  File "/Library/Frameworks/Python.framework/Versions/3.10/lib/python3.10/site-packages/flask/app.py", line 2080, in wsgi_app
    response = self.handle_exception(e)
  File "/Library/Frameworks/Python.framework/Versions/3.10/lib/python3.10/site-packages/flask_cors/extension.py", line 165, in wrapped_function
    return cors_after_request(app.make_response(f(*args, **kwargs)))
  File "/Library/Frameworks/Python.framework/Versions/3.10/lib/python3.10/site-packages/flask/app.py", line 2077, in wsgi_app
    response = self.full_dispatch_request()
  File "/Library/Frameworks/Python.framework/Versions/3.10/lib/python3.10/site-packages/flask/app.py", line 1525, in full_dispatch_request
    rv = self.handle_user_exception(e)
  File "/Library/Frameworks/Python.framework/Versions/3.10/lib/python3.10/site-packages/flask_cors/extension.py", line 165, in wrapped_function
    return cors_after_request(app.make_response(f(*args, **kwargs)))
  File "/Library/Frameworks/Python.framework/Versions/3.10/lib/python3.10/site-packages/flask/app.py", line 1523, in full_dispatch_request
    rv = self.dispatch_request()
  File "/Library/Frameworks/Python.framework/Versions/3.10/lib/python3.10/site-packages/flask/app.py", line 1509, in dispatch_request
    return self.ensure_sync(self.view_functions[rule.endpoint])(**req.view_args)
  File "/Users/michelecatani/Desktop/school/4semCompSci/3340/project/3340Project/back-end/flaskServer/items.py", line 26, in seeItem
    return jsonify(item.as_dict())
AttributeError: 'NoneType' object has no attribute 'as_dict'
127.0.0.1 - - [17/Jul/2022 17:00:27] "[35m[1mGET /items/seeItem?id=[object%20Object] HTTP/1.1[0m" 500 -
Traceback (most recent call last):
  File "/Library/Frameworks/Python.framework/Versions/3.10/lib/python3.10/site-packages/flask/app.py", line 2095, in __call__
    return self.wsgi_app(environ, start_response)
  File "/Library/Frameworks/Python.framework/Versions/3.10/lib/python3.10/site-packages/flask/app.py", line 2080, in wsgi_app
    response = self.handle_exception(e)
  File "/Library/Frameworks/Python.framework/Versions/3.10/lib/python3.10/site-packages/flask_cors/extension.py", line 165, in wrapped_function
    return cors_after_request(app.make_response(f(*args, **kwargs)))
  File "/Library/Frameworks/Python.framework/Versions/3.10/lib/python3.10/site-packages/flask/app.py", line 2077, in wsgi_app
    response = self.full_dispatch_request()
  File "/Library/Frameworks/Python.framework/Versions/3.10/lib/python3.10/site-packages/flask/app.py", line 1525, in full_dispatch_request
    rv = self.handle_user_exception(e)
  File "/Library/Frameworks/Python.framework/Versions/3.10/lib/python3.10/site-packages/flask_cors/extension.py", line 165, in wrapped_function
    return cors_after_request(app.make_response(f(*args, **kwargs)))
  File "/Library/Frameworks/Python.framework/Versions/3.10/lib/python3.10/site-packages/flask/app.py", line 1523, in full_dispatch_request
    rv = self.dispatch_request()
  File "/Library/Frameworks/Python.framework/Versions/3.10/lib/python3.10/site-packages/flask/app.py", line 1509, in dispatch_request
    return self.ensure_sync(self.view_functions[rule.endpoint])(**req.view_args)
  File "/Users/michelecatani/Desktop/school/4semCompSci/3340/project/3340Project/back-end/flaskServer/items.py", line 26, in seeItem
    return jsonify(item.as_dict())
AttributeError: 'NoneType' object has no attribute 'as_dict'
127.0.0.1 - - [17/Jul/2022 17:00:27] "[35m[1mGET /items/seeItem?id=[object%20Object] HTTP/1.1[0m" 500 -
Traceback (most recent call last):
  File "/Library/Frameworks/Python.framework/Versions/3.10/lib/python3.10/site-packages/flask/app.py", line 2095, in __call__
    return self.wsgi_app(environ, start_response)
  File "/Library/Frameworks/Python.framework/Versions/3.10/lib/python3.10/site-packages/flask/app.py", line 2080, in wsgi_app
    response = self.handle_exception(e)
  File "/Library/Frameworks/Python.framework/Versions/3.10/lib/python3.10/site-packages/flask_cors/extension.py", line 165, in wrapped_function
    return cors_after_request(app.make_response(f(*args, **kwargs)))
  File "/Library/Frameworks/Python.framework/Versions/3.10/lib/python3.10/site-packages/flask/app.py", line 2077, in wsgi_app
    response = self.full_dispatch_request()
  File "/Library/Frameworks/Python.framework/Versions/3.10/lib/python3.10/site-packages/flask/app.py", line 1525, in full_dispatch_request
    rv = self.handle_user_exception(e)
  File "/Library/Frameworks/Python.framework/Versions/3.10/lib/python3.10/site-packages/flask_cors/extension.py", line 165, in wrapped_function
    return cors_after_request(app.make_response(f(*args, **kwargs)))
  File "/Library/Frameworks/Python.framework/Versions/3.10/lib/python3.10/site-packages/flask/app.py", line 1523, in full_dispatch_request
    rv = self.dispatch_request()
  File "/Library/Frameworks/Python.framework/Versions/3.10/lib/python3.10/site-packages/flask/app.py", line 1509, in dispatch_request
    return self.ensure_sync(self.view_functions[rule.endpoint])(**req.view_args)
  File "/Users/michelecatani/Desktop/school/4semCompSci/3340/project/3340Project/back-end/flaskServer/items.py", line 26, in seeItem
    return jsonify(item.as_dict())
AttributeError: 'NoneType' object has no attribute 'as_dict'
127.0.0.1 - - [17/Jul/2022 17:00:32] "[35m[1mGET /items/seeItem?id=[object%20Object] HTTP/1.1[0m" 500 -
Traceback (most recent call last):
  File "/Library/Frameworks/Python.framework/Versions/3.10/lib/python3.10/site-packages/flask/app.py", line 2095, in __call__
    return self.wsgi_app(environ, start_response)
  File "/Library/Frameworks/Python.framework/Versions/3.10/lib/python3.10/site-packages/flask/app.py", line 2080, in wsgi_app
    response = self.handle_exception(e)
  File "/Library/Frameworks/Python.framework/Versions/3.10/lib/python3.10/site-packages/flask_cors/extension.py", line 165, in wrapped_function
    return cors_after_request(app.make_response(f(*args, **kwargs)))
  File "/Library/Frameworks/Python.framework/Versions/3.10/lib/python3.10/site-packages/flask/app.py", line 2077, in wsgi_app
    response = self.full_dispatch_request()
  File "/Library/Frameworks/Python.framework/Versions/3.10/lib/python3.10/site-packages/flask/app.py", line 1525, in full_dispatch_request
    rv = self.handle_user_exception(e)
  File "/Library/Frameworks/Python.framework/Versions/3.10/lib/python3.10/site-packages/flask_cors/extension.py", line 165, in wrapped_function
    return cors_after_request(app.make_response(f(*args, **kwargs)))
  File "/Library/Frameworks/Python.framework/Versions/3.10/lib/python3.10/site-packages/flask/app.py", line 1523, in full_dispatch_request
    rv = self.dispatch_request()
  File "/Library/Frameworks/Python.framework/Versions/3.10/lib/python3.10/site-packages/flask/app.py", line 1509, in dispatch_request
    return self.ensure_sync(self.view_functions[rule.endpoint])(**req.view_args)
  File "/Users/michelecatani/Desktop/school/4semCompSci/3340/project/3340Project/back-end/flaskServer/items.py", line 26, in seeItem
    return jsonify(item.as_dict())
AttributeError: 'NoneType' object has no attribute 'as_dict'
127.0.0.1 - - [17/Jul/2022 17:00:32] "[35m[1mGET /items/seeItem?id=[object%20Object] HTTP/1.1[0m" 500 -
Traceback (most recent call last):
  File "/Library/Frameworks/Python.framework/Versions/3.10/lib/python3.10/site-packages/flask/app.py", line 2095, in __call__
    return self.wsgi_app(environ, start_response)
  File "/Library/Frameworks/Python.framework/Versions/3.10/lib/python3.10/site-packages/flask/app.py", line 2080, in wsgi_app
    response = self.handle_exception(e)
  File "/Library/Frameworks/Python.framework/Versions/3.10/lib/python3.10/site-packages/flask_cors/extension.py", line 165, in wrapped_function
    return cors_after_request(app.make_response(f(*args, **kwargs)))
  File "/Library/Frameworks/Python.framework/Versions/3.10/lib/python3.10/site-packages/flask/app.py", line 2077, in wsgi_app
    response = self.full_dispatch_request()
  File "/Library/Frameworks/Python.framework/Versions/3.10/lib/python3.10/site-packages/flask/app.py", line 1525, in full_dispatch_request
    rv = self.handle_user_exception(e)
  File "/Library/Frameworks/Python.framework/Versions/3.10/lib/python3.10/site-packages/flask_cors/extension.py", line 165, in wrapped_function
    return cors_after_request(app.make_response(f(*args, **kwargs)))
  File "/Library/Frameworks/Python.framework/Versions/3.10/lib/python3.10/site-packages/flask/app.py", line 1523, in full_dispatch_request
    rv = self.dispatch_request()
  File "/Library/Frameworks/Python.framework/Versions/3.10/lib/python3.10/site-packages/flask/app.py", line 1509, in dispatch_request
    return self.ensure_sync(self.view_functions[rule.endpoint])(**req.view_args)
  File "/Users/michelecatani/Desktop/school/4semCompSci/3340/project/3340Project/back-end/flaskServer/items.py", line 26, in seeItem
    return jsonify(item.as_dict())
AttributeError: 'NoneType' object has no attribute 'as_dict'
127.0.0.1 - - [17/Jul/2022 17:00:34] "[35m[1mGET /items/seeItem?id=[object%20Object] HTTP/1.1[0m" 500 -
Traceback (most recent call last):
  File "/Library/Frameworks/Python.framework/Versions/3.10/lib/python3.10/site-packages/flask/app.py", line 2095, in __call__
    return self.wsgi_app(environ, start_response)
  File "/Library/Frameworks/Python.framework/Versions/3.10/lib/python3.10/site-packages/flask/app.py", line 2080, in wsgi_app
    response = self.handle_exception(e)
  File "/Library/Frameworks/Python.framework/Versions/3.10/lib/python3.10/site-packages/flask_cors/extension.py", line 165, in wrapped_function
    return cors_after_request(app.make_response(f(*args, **kwargs)))
  File "/Library/Frameworks/Python.framework/Versions/3.10/lib/python3.10/site-packages/flask/app.py", line 2077, in wsgi_app
    response = self.full_dispatch_request()
  File "/Library/Frameworks/Python.framework/Versions/3.10/lib/python3.10/site-packages/flask/app.py", line 1525, in full_dispatch_request
    rv = self.handle_user_exception(e)
  File "/Library/Frameworks/Python.framework/Versions/3.10/lib/python3.10/site-packages/flask_cors/extension.py", line 165, in wrapped_function
    return cors_after_request(app.make_response(f(*args, **kwargs)))
  File "/Library/Frameworks/Python.framework/Versions/3.10/lib/python3.10/site-packages/flask/app.py", line 1523, in full_dispatch_request
    rv = self.dispatch_request()
  File "/Library/Frameworks/Python.framework/Versions/3.10/lib/python3.10/site-packages/flask/app.py", line 1509, in dispatch_request
    return self.ensure_sync(self.view_functions[rule.endpoint])(**req.view_args)
  File "/Users/michelecatani/Desktop/school/4semCompSci/3340/project/3340Project/back-end/flaskServer/items.py", line 26, in seeItem
    return jsonify(item.as_dict())
AttributeError: 'NoneType' object has no attribute 'as_dict'
127.0.0.1 - - [17/Jul/2022 17:00:37] "GET /items/items HTTP/1.1" 200 -
127.0.0.1 - - [17/Jul/2022 17:00:37] "GET /items/items HTTP/1.1" 200 -
127.0.0.1 - - [17/Jul/2022 17:00:38] "GET /items/items HTTP/1.1" 200 -
127.0.0.1 - - [17/Jul/2022 17:00:38] "GET /items/items HTTP/1.1" 200 -
127.0.0.1 - - [17/Jul/2022 17:00:38] "[35m[1mGET /items/seeItem?id=[object%20Object] HTTP/1.1[0m" 500 -
Traceback (most recent call last):
  File "/Library/Frameworks/Python.framework/Versions/3.10/lib/python3.10/site-packages/flask/app.py", line 2095, in __call__
    return self.wsgi_app(environ, start_response)
  File "/Library/Frameworks/Python.framework/Versions/3.10/lib/python3.10/site-packages/flask/app.py", line 2080, in wsgi_app
    response = self.handle_exception(e)
  File "/Library/Frameworks/Python.framework/Versions/3.10/lib/python3.10/site-packages/flask_cors/extension.py", line 165, in wrapped_function
    return cors_after_request(app.make_response(f(*args, **kwargs)))
  File "/Library/Frameworks/Python.framework/Versions/3.10/lib/python3.10/site-packages/flask/app.py", line 2077, in wsgi_app
    response = self.full_dispatch_request()
  File "/Library/Frameworks/Python.framework/Versions/3.10/lib/python3.10/site-packages/flask/app.py", line 1525, in full_dispatch_request
    rv = self.handle_user_exception(e)
  File "/Library/Frameworks/Python.framework/Versions/3.10/lib/python3.10/site-packages/flask_cors/extension.py", line 165, in wrapped_function
    return cors_after_request(app.make_response(f(*args, **kwargs)))
  File "/Library/Frameworks/Python.framework/Versions/3.10/lib/python3.10/site-packages/flask/app.py", line 1523, in full_dispatch_request
    rv = self.dispatch_request()
  File "/Library/Frameworks/Python.framework/Versions/3.10/lib/python3.10/site-packages/flask/app.py", line 1509, in dispatch_request
    return self.ensure_sync(self.view_functions[rule.endpoint])(**req.view_args)
  File "/Users/michelecatani/Desktop/school/4semCompSci/3340/project/3340Project/back-end/flaskServer/items.py", line 26, in seeItem
    return jsonify(item.as_dict())
AttributeError: 'NoneType' object has no attribute 'as_dict'
127.0.0.1 - - [17/Jul/2022 17:01:33] "GET /items/items HTTP/1.1" 200 -
127.0.0.1 - - [17/Jul/2022 17:01:33] "GET /items/items HTTP/1.1" 200 -
127.0.0.1 - - [17/Jul/2022 17:03:45] "GET /items/items HTTP/1.1" 200 -
127.0.0.1 - - [17/Jul/2022 17:03:50] "GET /items/items HTTP/1.1" 200 -
127.0.0.1 - - [17/Jul/2022 17:03:55] "GET /items/seeItem?id=1 HTTP/1.1" 200 -
127.0.0.1 - - [17/Jul/2022 17:04:00] "GET /items/items HTTP/1.1" 200 -
127.0.0.1 - - [17/Jul/2022 17:04:00] "GET /items/items HTTP/1.1" 200 -
127.0.0.1 - - [17/Jul/2022 17:04:01] "GET /items/seeItem?id=1 HTTP/1.1" 200 -
127.0.0.1 - - [17/Jul/2022 17:04:19] "GET /items/items HTTP/1.1" 200 -
127.0.0.1 - - [17/Jul/2022 17:04:19] "GET /items/items HTTP/1.1" 200 -
127.0.0.1 - - [17/Jul/2022 17:04:20] "GET /items/seeItem?id=1 HTTP/1.1" 200 -
127.0.0.1 - - [17/Jul/2022 17:04:23] "GET /items/items HTTP/1.1" 200 -
127.0.0.1 - - [17/Jul/2022 17:04:23] "GET /items/items HTTP/1.1" 200 -
127.0.0.1 - - [17/Jul/2022 17:05:13] "GET /items/seeItem?id=1 HTTP/1.1" 200 -
127.0.0.1 - - [17/Jul/2022 17:05:15] "GET /items/items HTTP/1.1" 200 -
127.0.0.1 - - [17/Jul/2022 17:05:15] "GET /items/items HTTP/1.1" 200 -
127.0.0.1 - - [17/Jul/2022 17:05:15] "GET /items/seeItem?id=1 HTTP/1.1" 200 -
127.0.0.1 - - [17/Jul/2022 17:05:17] "GET /items/items HTTP/1.1" 200 -
127.0.0.1 - - [17/Jul/2022 17:05:17] "GET /items/items HTTP/1.1" 200 -
127.0.0.1 - - [17/Jul/2022 17:07:30] "GET /items/items HTTP/1.1" 200 -
127.0.0.1 - - [17/Jul/2022 17:07:32] "GET /items/items HTTP/1.1" 200 -
127.0.0.1 - - [17/Jul/2022 17:07:43] "GET /items/items HTTP/1.1" 200 -
127.0.0.1 - - [17/Jul/2022 17:07:46] "GET /items/items HTTP/1.1" 200 -
127.0.0.1 - - [17/Jul/2022 17:07:46] "GET /items/items HTTP/1.1" 200 -
127.0.0.1 - - [17/Jul/2022 17:07:47] "[35m[1mGET /items/seeItem?id=[object%20Object] HTTP/1.1[0m" 500 -
Traceback (most recent call last):
  File "/Library/Frameworks/Python.framework/Versions/3.10/lib/python3.10/site-packages/flask/app.py", line 2095, in __call__
    return self.wsgi_app(environ, start_response)
  File "/Library/Frameworks/Python.framework/Versions/3.10/lib/python3.10/site-packages/flask/app.py", line 2080, in wsgi_app
    response = self.handle_exception(e)
  File "/Library/Frameworks/Python.framework/Versions/3.10/lib/python3.10/site-packages/flask_cors/extension.py", line 165, in wrapped_function
    return cors_after_request(app.make_response(f(*args, **kwargs)))
  File "/Library/Frameworks/Python.framework/Versions/3.10/lib/python3.10/site-packages/flask/app.py", line 2077, in wsgi_app
    response = self.full_dispatch_request()
  File "/Library/Frameworks/Python.framework/Versions/3.10/lib/python3.10/site-packages/flask/app.py", line 1525, in full_dispatch_request
    rv = self.handle_user_exception(e)
  File "/Library/Frameworks/Python.framework/Versions/3.10/lib/python3.10/site-packages/flask_cors/extension.py", line 165, in wrapped_function
    return cors_after_request(app.make_response(f(*args, **kwargs)))
  File "/Library/Frameworks/Python.framework/Versions/3.10/lib/python3.10/site-packages/flask/app.py", line 1523, in full_dispatch_request
    rv = self.dispatch_request()
  File "/Library/Frameworks/Python.framework/Versions/3.10/lib/python3.10/site-packages/flask/app.py", line 1509, in dispatch_request
    return self.ensure_sync(self.view_functions[rule.endpoint])(**req.view_args)
  File "/Users/michelecatani/Desktop/school/4semCompSci/3340/project/3340Project/back-end/flaskServer/items.py", line 26, in seeItem
    return jsonify(item.as_dict())
AttributeError: 'NoneType' object has no attribute 'as_dict'
127.0.0.1 - - [17/Jul/2022 17:07:50] "GET /items/items HTTP/1.1" 200 -
127.0.0.1 - - [17/Jul/2022 17:07:50] "GET /items/items HTTP/1.1" 200 -
127.0.0.1 - - [17/Jul/2022 17:08:47] "GET /items/items HTTP/1.1" 200 -
127.0.0.1 - - [17/Jul/2022 17:08:54] "GET /items/items HTTP/1.1" 200 -
127.0.0.1 - - [17/Jul/2022 17:08:54] "GET /items/items HTTP/1.1" 200 -
127.0.0.1 - - [17/Jul/2022 17:08:55] "[35m[1mGET /items/seeItem?id=[object%20Object] HTTP/1.1[0m" 500 -
Traceback (most recent call last):
  File "/Library/Frameworks/Python.framework/Versions/3.10/lib/python3.10/site-packages/flask/app.py", line 2095, in __call__
    return self.wsgi_app(environ, start_response)
  File "/Library/Frameworks/Python.framework/Versions/3.10/lib/python3.10/site-packages/flask/app.py", line 2080, in wsgi_app
    response = self.handle_exception(e)
  File "/Library/Frameworks/Python.framework/Versions/3.10/lib/python3.10/site-packages/flask_cors/extension.py", line 165, in wrapped_function
    return cors_after_request(app.make_response(f(*args, **kwargs)))
  File "/Library/Frameworks/Python.framework/Versions/3.10/lib/python3.10/site-packages/flask/app.py", line 2077, in wsgi_app
    response = self.full_dispatch_request()
  File "/Library/Frameworks/Python.framework/Versions/3.10/lib/python3.10/site-packages/flask/app.py", line 1525, in full_dispatch_request
    rv = self.handle_user_exception(e)
  File "/Library/Frameworks/Python.framework/Versions/3.10/lib/python3.10/site-packages/flask_cors/extension.py", line 165, in wrapped_function
    return cors_after_request(app.make_response(f(*args, **kwargs)))
  File "/Library/Frameworks/Python.framework/Versions/3.10/lib/python3.10/site-packages/flask/app.py", line 1523, in full_dispatch_request
    rv = self.dispatch_request()
  File "/Library/Frameworks/Python.framework/Versions/3.10/lib/python3.10/site-packages/flask/app.py", line 1509, in dispatch_request
    return self.ensure_sync(self.view_functions[rule.endpoint])(**req.view_args)
  File "/Users/michelecatani/Desktop/school/4semCompSci/3340/project/3340Project/back-end/flaskServer/items.py", line 26, in seeItem
    return jsonify(item.as_dict())
AttributeError: 'NoneType' object has no attribute 'as_dict'
127.0.0.1 - - [17/Jul/2022 17:08:59] "GET /items/items HTTP/1.1" 200 -
127.0.0.1 - - [17/Jul/2022 17:08:59] "GET /items/items HTTP/1.1" 200 -
127.0.0.1 - - [17/Jul/2022 17:09:18] "[35m[1mGET /items/seeItem?id=[object%20Object] HTTP/1.1[0m" 500 -
Traceback (most recent call last):
  File "/Library/Frameworks/Python.framework/Versions/3.10/lib/python3.10/site-packages/flask/app.py", line 2095, in __call__
    return self.wsgi_app(environ, start_response)
  File "/Library/Frameworks/Python.framework/Versions/3.10/lib/python3.10/site-packages/flask/app.py", line 2080, in wsgi_app
    response = self.handle_exception(e)
  File "/Library/Frameworks/Python.framework/Versions/3.10/lib/python3.10/site-packages/flask_cors/extension.py", line 165, in wrapped_function
    return cors_after_request(app.make_response(f(*args, **kwargs)))
  File "/Library/Frameworks/Python.framework/Versions/3.10/lib/python3.10/site-packages/flask/app.py", line 2077, in wsgi_app
    response = self.full_dispatch_request()
  File "/Library/Frameworks/Python.framework/Versions/3.10/lib/python3.10/site-packages/flask/app.py", line 1525, in full_dispatch_request
    rv = self.handle_user_exception(e)
  File "/Library/Frameworks/Python.framework/Versions/3.10/lib/python3.10/site-packages/flask_cors/extension.py", line 165, in wrapped_function
    return cors_after_request(app.make_response(f(*args, **kwargs)))
  File "/Library/Frameworks/Python.framework/Versions/3.10/lib/python3.10/site-packages/flask/app.py", line 1523, in full_dispatch_request
    rv = self.dispatch_request()
  File "/Library/Frameworks/Python.framework/Versions/3.10/lib/python3.10/site-packages/flask/app.py", line 1509, in dispatch_request
    return self.ensure_sync(self.view_functions[rule.endpoint])(**req.view_args)
  File "/Users/michelecatani/Desktop/school/4semCompSci/3340/project/3340Project/back-end/flaskServer/items.py", line 26, in seeItem
    return jsonify(item.as_dict())
AttributeError: 'NoneType' object has no attribute 'as_dict'
127.0.0.1 - - [17/Jul/2022 17:09:21] "GET /items/items HTTP/1.1" 200 -
127.0.0.1 - - [17/Jul/2022 17:09:21] "GET /items/items HTTP/1.1" 200 -
127.0.0.1 - - [17/Jul/2022 17:11:30] "[35m[1mGET /items/seeItem?id=[object%20Object] HTTP/1.1[0m" 500 -
Traceback (most recent call last):
  File "/Library/Frameworks/Python.framework/Versions/3.10/lib/python3.10/site-packages/flask/app.py", line 2095, in __call__
    return self.wsgi_app(environ, start_response)
  File "/Library/Frameworks/Python.framework/Versions/3.10/lib/python3.10/site-packages/flask/app.py", line 2080, in wsgi_app
    response = self.handle_exception(e)
  File "/Library/Frameworks/Python.framework/Versions/3.10/lib/python3.10/site-packages/flask_cors/extension.py", line 165, in wrapped_function
    return cors_after_request(app.make_response(f(*args, **kwargs)))
  File "/Library/Frameworks/Python.framework/Versions/3.10/lib/python3.10/site-packages/flask/app.py", line 2077, in wsgi_app
    response = self.full_dispatch_request()
  File "/Library/Frameworks/Python.framework/Versions/3.10/lib/python3.10/site-packages/flask/app.py", line 1525, in full_dispatch_request
    rv = self.handle_user_exception(e)
  File "/Library/Frameworks/Python.framework/Versions/3.10/lib/python3.10/site-packages/flask_cors/extension.py", line 165, in wrapped_function
    return cors_after_request(app.make_response(f(*args, **kwargs)))
  File "/Library/Frameworks/Python.framework/Versions/3.10/lib/python3.10/site-packages/flask/app.py", line 1523, in full_dispatch_request
    rv = self.dispatch_request()
  File "/Library/Frameworks/Python.framework/Versions/3.10/lib/python3.10/site-packages/flask/app.py", line 1509, in dispatch_request
    return self.ensure_sync(self.view_functions[rule.endpoint])(**req.view_args)
  File "/Users/michelecatani/Desktop/school/4semCompSci/3340/project/3340Project/back-end/flaskServer/items.py", line 26, in seeItem
    return jsonify(item.as_dict())
AttributeError: 'NoneType' object has no attribute 'as_dict'
127.0.0.1 - - [17/Jul/2022 17:11:32] "GET /items/items HTTP/1.1" 200 -
127.0.0.1 - - [17/Jul/2022 17:11:32] "GET /items/items HTTP/1.1" 200 -
127.0.0.1 - - [17/Jul/2022 17:12:19] "[35m[1mGET /items/seeItem?id=[object%20Object] HTTP/1.1[0m" 500 -
Traceback (most recent call last):
  File "/Library/Frameworks/Python.framework/Versions/3.10/lib/python3.10/site-packages/flask/app.py", line 2095, in __call__
    return self.wsgi_app(environ, start_response)
  File "/Library/Frameworks/Python.framework/Versions/3.10/lib/python3.10/site-packages/flask/app.py", line 2080, in wsgi_app
    response = self.handle_exception(e)
  File "/Library/Frameworks/Python.framework/Versions/3.10/lib/python3.10/site-packages/flask_cors/extension.py", line 165, in wrapped_function
    return cors_after_request(app.make_response(f(*args, **kwargs)))
  File "/Library/Frameworks/Python.framework/Versions/3.10/lib/python3.10/site-packages/flask/app.py", line 2077, in wsgi_app
    response = self.full_dispatch_request()
  File "/Library/Frameworks/Python.framework/Versions/3.10/lib/python3.10/site-packages/flask/app.py", line 1525, in full_dispatch_request
    rv = self.handle_user_exception(e)
  File "/Library/Frameworks/Python.framework/Versions/3.10/lib/python3.10/site-packages/flask_cors/extension.py", line 165, in wrapped_function
    return cors_after_request(app.make_response(f(*args, **kwargs)))
  File "/Library/Frameworks/Python.framework/Versions/3.10/lib/python3.10/site-packages/flask/app.py", line 1523, in full_dispatch_request
    rv = self.dispatch_request()
  File "/Library/Frameworks/Python.framework/Versions/3.10/lib/python3.10/site-packages/flask/app.py", line 1509, in dispatch_request
    return self.ensure_sync(self.view_functions[rule.endpoint])(**req.view_args)
  File "/Users/michelecatani/Desktop/school/4semCompSci/3340/project/3340Project/back-end/flaskServer/items.py", line 26, in seeItem
    return jsonify(item.as_dict())
AttributeError: 'NoneType' object has no attribute 'as_dict'
127.0.0.1 - - [17/Jul/2022 17:12:27] "GET /items/items HTTP/1.1" 200 -
127.0.0.1 - - [17/Jul/2022 17:12:27] "GET /items/items HTTP/1.1" 200 -
127.0.0.1 - - [17/Jul/2022 17:12:38] "[35m[1mGET /items/seeItem?id=[object%20Object] HTTP/1.1[0m" 500 -
Traceback (most recent call last):
  File "/Library/Frameworks/Python.framework/Versions/3.10/lib/python3.10/site-packages/flask/app.py", line 2095, in __call__
    return self.wsgi_app(environ, start_response)
  File "/Library/Frameworks/Python.framework/Versions/3.10/lib/python3.10/site-packages/flask/app.py", line 2080, in wsgi_app
    response = self.handle_exception(e)
  File "/Library/Frameworks/Python.framework/Versions/3.10/lib/python3.10/site-packages/flask_cors/extension.py", line 165, in wrapped_function
    return cors_after_request(app.make_response(f(*args, **kwargs)))
  File "/Library/Frameworks/Python.framework/Versions/3.10/lib/python3.10/site-packages/flask/app.py", line 2077, in wsgi_app
    response = self.full_dispatch_request()
  File "/Library/Frameworks/Python.framework/Versions/3.10/lib/python3.10/site-packages/flask/app.py", line 1525, in full_dispatch_request
    rv = self.handle_user_exception(e)
  File "/Library/Frameworks/Python.framework/Versions/3.10/lib/python3.10/site-packages/flask_cors/extension.py", line 165, in wrapped_function
    return cors_after_request(app.make_response(f(*args, **kwargs)))
  File "/Library/Frameworks/Python.framework/Versions/3.10/lib/python3.10/site-packages/flask/app.py", line 1523, in full_dispatch_request
    rv = self.dispatch_request()
  File "/Library/Frameworks/Python.framework/Versions/3.10/lib/python3.10/site-packages/flask/app.py", line 1509, in dispatch_request
    return self.ensure_sync(self.view_functions[rule.endpoint])(**req.view_args)
  File "/Users/michelecatani/Desktop/school/4semCompSci/3340/project/3340Project/back-end/flaskServer/items.py", line 26, in seeItem
    return jsonify(item.as_dict())
AttributeError: 'NoneType' object has no attribute 'as_dict'
127.0.0.1 - - [17/Jul/2022 17:12:41] "GET /items/items HTTP/1.1" 200 -
127.0.0.1 - - [17/Jul/2022 17:12:41] "GET /items/items HTTP/1.1" 200 -
127.0.0.1 - - [17/Jul/2022 17:13:23] "GET /items/items HTTP/1.1" 200 -
127.0.0.1 - - [17/Jul/2022 17:13:25] "GET /items/seeItem?id=1 HTTP/1.1" 200 -
127.0.0.1 - - [17/Jul/2022 17:13:32] "GET /items/items HTTP/1.1" 200 -
127.0.0.1 - - [17/Jul/2022 17:13:32] "GET /items/items HTTP/1.1" 200 -
127.0.0.1 - - [17/Jul/2022 17:13:44] "GET /items/items HTTP/1.1" 200 -
127.0.0.1 - - [17/Jul/2022 17:14:01] "GET /items/items HTTP/1.1" 200 -
127.0.0.1 - - [17/Jul/2022 17:14:07] "GET /items/items HTTP/1.1" 200 -
127.0.0.1 - - [17/Jul/2022 17:14:10] "[35m[1mGET /items/seeItem?id=[object%20Object] HTTP/1.1[0m" 500 -
Traceback (most recent call last):
  File "/Library/Frameworks/Python.framework/Versions/3.10/lib/python3.10/site-packages/flask/app.py", line 2095, in __call__
    return self.wsgi_app(environ, start_response)
  File "/Library/Frameworks/Python.framework/Versions/3.10/lib/python3.10/site-packages/flask/app.py", line 2080, in wsgi_app
    response = self.handle_exception(e)
  File "/Library/Frameworks/Python.framework/Versions/3.10/lib/python3.10/site-packages/flask_cors/extension.py", line 165, in wrapped_function
    return cors_after_request(app.make_response(f(*args, **kwargs)))
  File "/Library/Frameworks/Python.framework/Versions/3.10/lib/python3.10/site-packages/flask/app.py", line 2077, in wsgi_app
    response = self.full_dispatch_request()
  File "/Library/Frameworks/Python.framework/Versions/3.10/lib/python3.10/site-packages/flask/app.py", line 1525, in full_dispatch_request
    rv = self.handle_user_exception(e)
  File "/Library/Frameworks/Python.framework/Versions/3.10/lib/python3.10/site-packages/flask_cors/extension.py", line 165, in wrapped_function
    return cors_after_request(app.make_response(f(*args, **kwargs)))
  File "/Library/Frameworks/Python.framework/Versions/3.10/lib/python3.10/site-packages/flask/app.py", line 1523, in full_dispatch_request
    rv = self.dispatch_request()
  File "/Library/Frameworks/Python.framework/Versions/3.10/lib/python3.10/site-packages/flask/app.py", line 1509, in dispatch_request
    return self.ensure_sync(self.view_functions[rule.endpoint])(**req.view_args)
  File "/Users/michelecatani/Desktop/school/4semCompSci/3340/project/3340Project/back-end/flaskServer/items.py", line 26, in seeItem
    return jsonify(item.as_dict())
AttributeError: 'NoneType' object has no attribute 'as_dict'
127.0.0.1 - - [17/Jul/2022 17:14:14] "GET /items/items HTTP/1.1" 200 -
127.0.0.1 - - [17/Jul/2022 17:14:14] "GET /items/items HTTP/1.1" 200 -
127.0.0.1 - - [17/Jul/2022 17:15:01] "GET /items/items HTTP/1.1" 200 -
127.0.0.1 - - [17/Jul/2022 17:15:01] "GET /items/items HTTP/1.1" 200 -
127.0.0.1 - - [17/Jul/2022 17:15:03] "[35m[1mGET /items/seeItem?id=[object%20Object] HTTP/1.1[0m" 500 -
Traceback (most recent call last):
  File "/Library/Frameworks/Python.framework/Versions/3.10/lib/python3.10/site-packages/flask/app.py", line 2095, in __call__
    return self.wsgi_app(environ, start_response)
  File "/Library/Frameworks/Python.framework/Versions/3.10/lib/python3.10/site-packages/flask/app.py", line 2080, in wsgi_app
    response = self.handle_exception(e)
  File "/Library/Frameworks/Python.framework/Versions/3.10/lib/python3.10/site-packages/flask_cors/extension.py", line 165, in wrapped_function
    return cors_after_request(app.make_response(f(*args, **kwargs)))
  File "/Library/Frameworks/Python.framework/Versions/3.10/lib/python3.10/site-packages/flask/app.py", line 2077, in wsgi_app
    response = self.full_dispatch_request()
  File "/Library/Frameworks/Python.framework/Versions/3.10/lib/python3.10/site-packages/flask/app.py", line 1525, in full_dispatch_request
    rv = self.handle_user_exception(e)
  File "/Library/Frameworks/Python.framework/Versions/3.10/lib/python3.10/site-packages/flask_cors/extension.py", line 165, in wrapped_function
    return cors_after_request(app.make_response(f(*args, **kwargs)))
  File "/Library/Frameworks/Python.framework/Versions/3.10/lib/python3.10/site-packages/flask/app.py", line 1523, in full_dispatch_request
    rv = self.dispatch_request()
  File "/Library/Frameworks/Python.framework/Versions/3.10/lib/python3.10/site-packages/flask/app.py", line 1509, in dispatch_request
    return self.ensure_sync(self.view_functions[rule.endpoint])(**req.view_args)
  File "/Users/michelecatani/Desktop/school/4semCompSci/3340/project/3340Project/back-end/flaskServer/items.py", line 26, in seeItem
    return jsonify(item.as_dict())
AttributeError: 'NoneType' object has no attribute 'as_dict'
127.0.0.1 - - [17/Jul/2022 17:15:08] "GET /items/items HTTP/1.1" 200 -
127.0.0.1 - - [17/Jul/2022 17:15:08] "GET /items/items HTTP/1.1" 200 -
127.0.0.1 - - [17/Jul/2022 17:15:14] "GET /items/items HTTP/1.1" 200 -
127.0.0.1 - - [17/Jul/2022 17:16:56] "GET /items/items HTTP/1.1" 200 -
127.0.0.1 - - [17/Jul/2022 17:17:04] "GET /items/seeItem?id=1 HTTP/1.1" 200 -
127.0.0.1 - - [17/Jul/2022 17:17:07] "GET /items/items HTTP/1.1" 200 -
127.0.0.1 - - [17/Jul/2022 17:17:07] "GET /items/items HTTP/1.1" 200 -
127.0.0.1 - - [17/Jul/2022 17:17:07] "GET /items/seeItem?id=14 HTTP/1.1" 200 -
127.0.0.1 - - [17/Jul/2022 17:18:27] "GET /items/items HTTP/1.1" 200 -
127.0.0.1 - - [17/Jul/2022 17:18:27] "GET /items/items HTTP/1.1" 200 -
127.0.0.1 - - [17/Jul/2022 17:20:02] "GET /items/items HTTP/1.1" 200 -
127.0.0.1 - - [17/Jul/2022 17:20:06] "GET /items/items HTTP/1.1" 200 -
127.0.0.1 - - [17/Jul/2022 17:20:07] "GET /items/seeItem?id=1 HTTP/1.1" 200 -
127.0.0.1 - - [17/Jul/2022 17:20:10] "GET /items/items HTTP/1.1" 200 -
127.0.0.1 - - [17/Jul/2022 17:20:10] "GET /items/items HTTP/1.1" 200 -
127.0.0.1 - - [17/Jul/2022 17:20:32] "GET /items/seeItem?id=1 HTTP/1.1" 200 -
127.0.0.1 - - [17/Jul/2022 17:20:36] "GET /items/items HTTP/1.1" 200 -
127.0.0.1 - - [17/Jul/2022 17:20:36] "GET /items/items HTTP/1.1" 200 -
127.0.0.1 - - [17/Jul/2022 17:20:37] "GET /items/seeItem?id=14 HTTP/1.1" 200 -
127.0.0.1 - - [17/Jul/2022 17:20:39] "GET /items/items HTTP/1.1" 200 -
127.0.0.1 - - [17/Jul/2022 17:20:39] "GET /items/items HTTP/1.1" 200 -
127.0.0.1 - - [17/Jul/2022 17:20:40] "GET /items/seeItem?id=1 HTTP/1.1" 200 -
 * Detected change in '/Users/michelecatani/Desktop/school/4semCompSci/3340/project/3340Project/back-end/flaskServer/items.py', reloading
 * Restarting with stat
 * Debugger is active!
 * Debugger PIN: 371-262-178
/Library/Frameworks/Python.framework/Versions/3.10/lib/python3.10/site-packages/flask_sqlalchemy/__init__.py:872: FSADeprecationWarning: SQLALCHEMY_TRACK_MODIFICATIONS adds significant overhead and will be disabled by default in the future.  Set it to True or False to suppress this warning.
  warnings.warn(FSADeprecationWarning(
Created Database!
 * Detected change in '/Users/michelecatani/Desktop/school/4semCompSci/3340/project/3340Project/back-end/flaskServer/items.py', reloading
 * Restarting with stat
 * Debugger is active!
 * Debugger PIN: 371-262-178
/Library/Frameworks/Python.framework/Versions/3.10/lib/python3.10/site-packages/flask_sqlalchemy/__init__.py:872: FSADeprecationWarning: SQLALCHEMY_TRACK_MODIFICATIONS adds significant overhead and will be disabled by default in the future.  Set it to True or False to suppress this warning.
  warnings.warn(FSADeprecationWarning(
Created Database!
 * Detected change in '/Users/michelecatani/Desktop/school/4semCompSci/3340/project/3340Project/back-end/flaskServer/items.py', reloading
 * Restarting with stat
 * Debugger is active!
 * Debugger PIN: 371-262-178
/Library/Frameworks/Python.framework/Versions/3.10/lib/python3.10/site-packages/flask_sqlalchemy/__init__.py:872: FSADeprecationWarning: SQLALCHEMY_TRACK_MODIFICATIONS adds significant overhead and will be disabled by default in the future.  Set it to True or False to suppress this warning.
  warnings.warn(FSADeprecationWarning(
Created Database!
 * Detected change in '/Users/michelecatani/Desktop/school/4semCompSci/3340/project/3340Project/back-end/flaskServer/items.py', reloading
 * Restarting with stat
 * Debugger is active!
 * Debugger PIN: 371-262-178
/Library/Frameworks/Python.framework/Versions/3.10/lib/python3.10/site-packages/flask_sqlalchemy/__init__.py:872: FSADeprecationWarning: SQLALCHEMY_TRACK_MODIFICATIONS adds significant overhead and will be disabled by default in the future.  Set it to True or False to suppress this warning.
  warnings.warn(FSADeprecationWarning(
Created Database!
 * Detected change in '/Users/michelecatani/Desktop/school/4semCompSci/3340/project/3340Project/back-end/flaskServer/items.py', reloading
 * Restarting with stat
 * Debugger is active!
 * Debugger PIN: 371-262-178
/Library/Frameworks/Python.framework/Versions/3.10/lib/python3.10/site-packages/flask_sqlalchemy/__init__.py:872: FSADeprecationWarning: SQLALCHEMY_TRACK_MODIFICATIONS adds significant overhead and will be disabled by default in the future.  Set it to True or False to suppress this warning.
  warnings.warn(FSADeprecationWarning(
Created Database!
127.0.0.1 - - [17/Jul/2022 17:22:37] "GET /items/items HTTP/1.1" 200 -
127.0.0.1 - - [17/Jul/2022 17:22:37] "GET /items/items HTTP/1.1" 200 -
127.0.0.1 - - [17/Jul/2022 17:22:42] "GET /items/seeItem?id=14 HTTP/1.1" 200 -
127.0.0.1 - - [17/Jul/2022 17:22:44] "GET /items/items HTTP/1.1" 200 -
127.0.0.1 - - [17/Jul/2022 17:22:44] "GET /items/items HTTP/1.1" 200 -
127.0.0.1 - - [17/Jul/2022 17:22:44] "GET /items/seeItem?id=1 HTTP/1.1" 200 -
127.0.0.1 - - [17/Jul/2022 17:22:45] "GET /items/items HTTP/1.1" 200 -
127.0.0.1 - - [17/Jul/2022 17:22:45] "GET /items/items HTTP/1.1" 200 -
127.0.0.1 - - [17/Jul/2022 17:23:45] "GET /items/seeItem?id=1 HTTP/1.1" 200 -
127.0.0.1 - - [17/Jul/2022 17:23:48] "GET /items/items HTTP/1.1" 200 -
127.0.0.1 - - [17/Jul/2022 17:23:48] "GET /items/items HTTP/1.1" 200 -
127.0.0.1 - - [17/Jul/2022 17:23:48] "GET /items/seeItem?id=14 HTTP/1.1" 200 -
127.0.0.1 - - [17/Jul/2022 17:23:52] "GET /items/items HTTP/1.1" 200 -
127.0.0.1 - - [17/Jul/2022 17:23:52] "GET /items/items HTTP/1.1" 200 -
127.0.0.1 - - [17/Jul/2022 17:23:53] "GET /items/seeItem?id=1 HTTP/1.1" 200 -
127.0.0.1 - - [17/Jul/2022 17:23:54] "GET /items/items HTTP/1.1" 200 -
127.0.0.1 - - [17/Jul/2022 17:23:54] "GET /items/items HTTP/1.1" 200 -
127.0.0.1 - - [17/Jul/2022 17:23:55] "GET /items/seeItem?id=14 HTTP/1.1" 200 -
127.0.0.1 - - [17/Jul/2022 17:24:00] "GET /items/items HTTP/1.1" 200 -
127.0.0.1 - - [17/Jul/2022 17:24:00] "GET /items/items HTTP/1.1" 200 -
127.0.0.1 - - [17/Jul/2022 17:24:01] "GET /items/seeItem?id=1 HTTP/1.1" 200 -
127.0.0.1 - - [17/Jul/2022 17:24:03] "GET /items/items HTTP/1.1" 200 -
127.0.0.1 - - [17/Jul/2022 17:24:03] "GET /items/items HTTP/1.1" 200 -
127.0.0.1 - - [17/Jul/2022 17:24:03] "GET /items/seeItem?id=14 HTTP/1.1" 200 -
 * Detected change in '/Users/michelecatani/Desktop/school/4semCompSci/3340/project/3340Project/back-end/flaskServer/models.py', reloading
 * Restarting with stat
 * Debugger is active!
 * Debugger PIN: 371-262-178
/Library/Frameworks/Python.framework/Versions/3.10/lib/python3.10/site-packages/flask_sqlalchemy/__init__.py:872: FSADeprecationWarning: SQLALCHEMY_TRACK_MODIFICATIONS adds significant overhead and will be disabled by default in the future.  Set it to True or False to suppress this warning.
  warnings.warn(FSADeprecationWarning(
Created Database!
127.0.0.1 - - [17/Jul/2022 17:24:45] "[35m[1mGET /items/seeItem?id=about HTTP/1.1[0m" 500 -
Traceback (most recent call last):
  File "/Library/Frameworks/Python.framework/Versions/3.10/lib/python3.10/site-packages/flask/app.py", line 2095, in __call__
    return self.wsgi_app(environ, start_response)
  File "/Library/Frameworks/Python.framework/Versions/3.10/lib/python3.10/site-packages/flask/app.py", line 2080, in wsgi_app
    response = self.handle_exception(e)
  File "/Library/Frameworks/Python.framework/Versions/3.10/lib/python3.10/site-packages/flask_cors/extension.py", line 165, in wrapped_function
    return cors_after_request(app.make_response(f(*args, **kwargs)))
  File "/Library/Frameworks/Python.framework/Versions/3.10/lib/python3.10/site-packages/flask/app.py", line 2077, in wsgi_app
    response = self.full_dispatch_request()
  File "/Library/Frameworks/Python.framework/Versions/3.10/lib/python3.10/site-packages/flask/app.py", line 1525, in full_dispatch_request
    rv = self.handle_user_exception(e)
  File "/Library/Frameworks/Python.framework/Versions/3.10/lib/python3.10/site-packages/flask_cors/extension.py", line 165, in wrapped_function
    return cors_after_request(app.make_response(f(*args, **kwargs)))
  File "/Library/Frameworks/Python.framework/Versions/3.10/lib/python3.10/site-packages/flask/app.py", line 1523, in full_dispatch_request
    rv = self.dispatch_request()
  File "/Library/Frameworks/Python.framework/Versions/3.10/lib/python3.10/site-packages/flask/app.py", line 1509, in dispatch_request
    return self.ensure_sync(self.view_functions[rule.endpoint])(**req.view_args)
  File "/Users/michelecatani/Desktop/school/4semCompSci/3340/project/3340Project/back-end/flaskServer/items.py", line 29, in seeItem
    return jsonify(item.as_dict())
AttributeError: 'NoneType' object has no attribute 'as_dict'
127.0.0.1 - - [17/Jul/2022 17:24:49] "GET /items/seeItem?id=14 HTTP/1.1" 200 -
127.0.0.1 - - [17/Jul/2022 17:24:50] "[35m[1mGET /items/seeItem?id=about HTTP/1.1[0m" 500 -
Traceback (most recent call last):
  File "/Library/Frameworks/Python.framework/Versions/3.10/lib/python3.10/site-packages/flask/app.py", line 2095, in __call__
    return self.wsgi_app(environ, start_response)
  File "/Library/Frameworks/Python.framework/Versions/3.10/lib/python3.10/site-packages/flask/app.py", line 2080, in wsgi_app
    response = self.handle_exception(e)
  File "/Library/Frameworks/Python.framework/Versions/3.10/lib/python3.10/site-packages/flask_cors/extension.py", line 165, in wrapped_function
    return cors_after_request(app.make_response(f(*args, **kwargs)))
  File "/Library/Frameworks/Python.framework/Versions/3.10/lib/python3.10/site-packages/flask/app.py", line 2077, in wsgi_app
    response = self.full_dispatch_request()
  File "/Library/Frameworks/Python.framework/Versions/3.10/lib/python3.10/site-packages/flask/app.py", line 1525, in full_dispatch_request
    rv = self.handle_user_exception(e)
  File "/Library/Frameworks/Python.framework/Versions/3.10/lib/python3.10/site-packages/flask_cors/extension.py", line 165, in wrapped_function
    return cors_after_request(app.make_response(f(*args, **kwargs)))
  File "/Library/Frameworks/Python.framework/Versions/3.10/lib/python3.10/site-packages/flask/app.py", line 1523, in full_dispatch_request
    rv = self.dispatch_request()
  File "/Library/Frameworks/Python.framework/Versions/3.10/lib/python3.10/site-packages/flask/app.py", line 1509, in dispatch_request
    return self.ensure_sync(self.view_functions[rule.endpoint])(**req.view_args)
  File "/Users/michelecatani/Desktop/school/4semCompSci/3340/project/3340Project/back-end/flaskServer/items.py", line 29, in seeItem
    return jsonify(item.as_dict())
AttributeError: 'NoneType' object has no attribute 'as_dict'
127.0.0.1 - - [17/Jul/2022 17:24:56] "GET /items/seeItem?id=14 HTTP/1.1" 200 -
127.0.0.1 - - [17/Jul/2022 17:25:00] "GET /items/items HTTP/1.1" 200 -
127.0.0.1 - - [17/Jul/2022 17:25:00] "GET /items/items HTTP/1.1" 200 -
127.0.0.1 - - [17/Jul/2022 17:25:08] "GET /auth/ourNames HTTP/1.1" 200 -
127.0.0.1 - - [17/Jul/2022 17:25:08] "GET /auth/ourNames HTTP/1.1" 200 -
127.0.0.1 - - [17/Jul/2022 17:25:09] "GET /items/items HTTP/1.1" 200 -
127.0.0.1 - - [17/Jul/2022 17:25:09] "GET /items/items HTTP/1.1" 200 -
127.0.0.1 - - [17/Jul/2022 17:25:10] "[35m[1mGET /items/seeItem?id=about HTTP/1.1[0m" 500 -
Traceback (most recent call last):
  File "/Library/Frameworks/Python.framework/Versions/3.10/lib/python3.10/site-packages/flask/app.py", line 2095, in __call__
    return self.wsgi_app(environ, start_response)
  File "/Library/Frameworks/Python.framework/Versions/3.10/lib/python3.10/site-packages/flask/app.py", line 2080, in wsgi_app
    response = self.handle_exception(e)
  File "/Library/Frameworks/Python.framework/Versions/3.10/lib/python3.10/site-packages/flask_cors/extension.py", line 165, in wrapped_function
    return cors_after_request(app.make_response(f(*args, **kwargs)))
  File "/Library/Frameworks/Python.framework/Versions/3.10/lib/python3.10/site-packages/flask/app.py", line 2077, in wsgi_app
    response = self.full_dispatch_request()
  File "/Library/Frameworks/Python.framework/Versions/3.10/lib/python3.10/site-packages/flask/app.py", line 1525, in full_dispatch_request
    rv = self.handle_user_exception(e)
  File "/Library/Frameworks/Python.framework/Versions/3.10/lib/python3.10/site-packages/flask_cors/extension.py", line 165, in wrapped_function
    return cors_after_request(app.make_response(f(*args, **kwargs)))
  File "/Library/Frameworks/Python.framework/Versions/3.10/lib/python3.10/site-packages/flask/app.py", line 1523, in full_dispatch_request
    rv = self.dispatch_request()
  File "/Library/Frameworks/Python.framework/Versions/3.10/lib/python3.10/site-packages/flask/app.py", line 1509, in dispatch_request
    return self.ensure_sync(self.view_functions[rule.endpoint])(**req.view_args)
  File "/Users/michelecatani/Desktop/school/4semCompSci/3340/project/3340Project/back-end/flaskServer/items.py", line 29, in seeItem
    return jsonify(item.as_dict())
AttributeError: 'NoneType' object has no attribute 'as_dict'
127.0.0.1 - - [17/Jul/2022 17:25:16] "GET /items/items HTTP/1.1" 200 -
127.0.0.1 - - [17/Jul/2022 17:25:16] "GET /items/items HTTP/1.1" 200 -
127.0.0.1 - - [17/Jul/2022 17:25:38] "[35m[1mGET /items/seeItem?id=about HTTP/1.1[0m" 500 -
Traceback (most recent call last):
  File "/Library/Frameworks/Python.framework/Versions/3.10/lib/python3.10/site-packages/flask/app.py", line 2095, in __call__
    return self.wsgi_app(environ, start_response)
  File "/Library/Frameworks/Python.framework/Versions/3.10/lib/python3.10/site-packages/flask/app.py", line 2080, in wsgi_app
    response = self.handle_exception(e)
  File "/Library/Frameworks/Python.framework/Versions/3.10/lib/python3.10/site-packages/flask_cors/extension.py", line 165, in wrapped_function
    return cors_after_request(app.make_response(f(*args, **kwargs)))
  File "/Library/Frameworks/Python.framework/Versions/3.10/lib/python3.10/site-packages/flask/app.py", line 2077, in wsgi_app
    response = self.full_dispatch_request()
  File "/Library/Frameworks/Python.framework/Versions/3.10/lib/python3.10/site-packages/flask/app.py", line 1525, in full_dispatch_request
    rv = self.handle_user_exception(e)
  File "/Library/Frameworks/Python.framework/Versions/3.10/lib/python3.10/site-packages/flask_cors/extension.py", line 165, in wrapped_function
    return cors_after_request(app.make_response(f(*args, **kwargs)))
  File "/Library/Frameworks/Python.framework/Versions/3.10/lib/python3.10/site-packages/flask/app.py", line 1523, in full_dispatch_request
    rv = self.dispatch_request()
  File "/Library/Frameworks/Python.framework/Versions/3.10/lib/python3.10/site-packages/flask/app.py", line 1509, in dispatch_request
    return self.ensure_sync(self.view_functions[rule.endpoint])(**req.view_args)
  File "/Users/michelecatani/Desktop/school/4semCompSci/3340/project/3340Project/back-end/flaskServer/items.py", line 29, in seeItem
    return jsonify(item.as_dict())
AttributeError: 'NoneType' object has no attribute 'as_dict'
127.0.0.1 - - [17/Jul/2022 17:25:41] "GET /items/items HTTP/1.1" 200 -
127.0.0.1 - - [17/Jul/2022 17:25:41] "GET /items/items HTTP/1.1" 200 -
127.0.0.1 - - [17/Jul/2022 17:26:07] "GET /auth/ourNames HTTP/1.1" 200 -
127.0.0.1 - - [17/Jul/2022 17:26:07] "GET /auth/ourNames HTTP/1.1" 200 -
127.0.0.1 - - [17/Jul/2022 17:26:08] "GET /items/items HTTP/1.1" 200 -
127.0.0.1 - - [17/Jul/2022 17:26:08] "GET /items/items HTTP/1.1" 200 -
127.0.0.1 - - [17/Jul/2022 17:26:21] "GET /auth/ourNames HTTP/1.1" 200 -
127.0.0.1 - - [17/Jul/2022 17:26:21] "GET /auth/ourNames HTTP/1.1" 200 -
127.0.0.1 - - [17/Jul/2022 17:26:24] "GET /items/items HTTP/1.1" 200 -
127.0.0.1 - - [17/Jul/2022 17:26:24] "GET /items/items HTTP/1.1" 200 -
127.0.0.1 - - [17/Jul/2022 17:26:26] "GET /items/seeItem?id=1 HTTP/1.1" 200 -
127.0.0.1 - - [17/Jul/2022 17:26:28] "GET /items/items HTTP/1.1" 200 -
127.0.0.1 - - [17/Jul/2022 17:26:28] "GET /items/items HTTP/1.1" 200 -
